Workbook

Sheet Summary by RFM
C3: Champions | F3: Potential Loyalist | I3: Value Conscious Loyals | L3: Total Top 3 Segements | O3: Total All Scene+ Members
B4: Time Period - FY 2025 | C4: Is Cineclub | E4: % Change | F4: Is Cineclub | H4: % Change | I4: Is Cineclub | K4: % Change | L4: Is Cineclub | N4: % Change | O4: Is Cineclub | Q4: % Change
C5: No | D5: Yes | F5: No | G5: Yes | I5: No | J5: Yes | L5: No | M5: Yes | O5: No | P5: Yes
B6: No of Members | C6: 159430 | D6: 79346 | E6: - | F6: 613487 | G6: 87485 | H6: - | I6: 85775 | J6: 14678 | K6: - | L6: 858692 | M6: 181509 | N6: - | O6: 3635558 | P6: 217835 | Q6: -
B7: Avg Frequency | C7: 10.755084 | D7: 14.95478 | E7: =(D7/C7)-1 -> 0.39048479 | F7: 5.782918 | G7: 9.931051 | H7: =(G7/F7)-1 -> 0.71730795 | I7: 10.123987 | J7: 17.631285 | K7: =(J7/I7)-1 -> 0.74153568 | L7: 7.1397113 | M7: 12.749847 | N7: =(M7/L7)-1 -> 0.78576507 | O7: 2.941563 | P7: 10.996695 | Q7: =(P7/O7)-1 -> 2.7383849
B8: Avg Total Spend per visit | C8: 50.613065 | D8: 47.386639 | E8: =(D8/C8)-1 -> -0.0637469 | F8: 42.870543 | G8: 34.377079 | H8: =(G8/F8)-1 -> -0.19811888 | I8: 13.792513 | J8: 15.792556 | K8: =(J8/I8)-1 -> 0.14500932 | L8: 40.917302 | M8: 38.969417 | N8: =(M8/L8)-1 -> -0.047605412 | O8: 41.945338 | P8: 39.245078 | Q8: =(P8/O8)-1 -> -0.064375688
B9: Avg Ticket Spend per visit | C9: 29.841093 | D9: 27.665523 | E9: =(D9/C9)-1 -> -0.072905171 | F9: 26.408159 | G9: 22.353575 | H9: =(G9/F9)-1 -> -0.15353528 | I9: 8.01329 | J9: 12.184674 | K9: =(J9/I9)-1 -> 0.52055822 | L9: 24.762792 | M9: 23.940092 | N9: =(M9/L9)-1 -> -0.033223233 | O9: 25.475662 | P9: 24.179378 | Q9: =(P9/O9)-1 -> -0.050883231
B10: Avg Concession Spend per visit | C10: 20.771971 | D10: 19.721116 | E10: =(D10/C10)-1 -> -0.050590048 | F10: 16.462384 | G10: 12.023504 | H10: =(G10/F10)-1 -> -0.26963774 | I10: 5.779224 | J10: 3.607882 | K10: =(J10/I10)-1 -> -0.37571515 | L10: 16.15451 | M10: 15.029324 | N10: =(M10/L10)-1 -> -0.069651509 | O10: 16.469676 | P10: 15.0657 | Q10: =(P10/O10)-1 -> -0.085246121
B11: Total Spend per person in a year | C11: 544.34775 | D11: 708.65677 | E11: =(D11/C11)-1 -> 0.30184569 | F11: 247.91683 | G11: 341.40052 | H11: =(G11/F11)-1 -> 0.37707683 | I11: 139.63523 | J11: 278.44306 | K11: =(J11/I11)-1 -> 0.99407457 | L11: 292.13772 | M11: 496.85411 | N11: =(M11/L11)-1 -> 0.70075298 | O11: 123.38486 | P11: 431.56614 | Q11: =(P11/O11)-1 -> 2.4977238
B12: Ticket Spend per person in a year | C12: 320.94346 | D12: 413.73181 | E12: =(D12/C12)-1 -> 0.28911122 | F12: 152.71622 | G12: 221.9945 | H12: =(G12/F12)-1 -> 0.45364063 | I12: 81.126444 | J12: 214.83146 | K12: =(J12/I12)-1 -> 1.6481065 | L12: 176.79919 | M12: 305.23252 | N12: =(M12/L12)-1 -> 0.72643619 | O12: 74.938266 | P12: 265.89324 | Q12: =(P12/O12)-1 -> 2.5481637
B13: Concession Spend per person in a year | C13: 223.40429 | D13: 294.92496 | E13: =(D13/C13)-1 -> 0.32014007 | F13: 95.200617 | G13: 119.40603 | H13: =(G13/F13)-1 -> 0.25425688 | I13: 58.508785 | J13: 63.611596 | K13: =(J13/I13)-1 -> 0.087214441 | L13: 115.33854 | M13: 191.62159 | N13: =(M13/L13)-1 -> 0.66138392 | O13: 48.446589 | P13: 165.6729 | Q13: =(P13/O13)-1 -> 2.4197021
B14: Concession Incidence | C14: 0.72861981 | D14: 0.79147937 | E14: =(D14/C14)-1 -> 0.086272096 | F14: 0.63693501 | G14: 0.62721076 | H14: =(G14/F14)-1 -> -0.015267254 | I14: 0.55221935 | J14: 0.3593465 | K14: =(J14/I14)-1 -> -0.34926854 | L14: 0.65057832 | M14: 0.68148424 | N14: =(M14/L14)-1 -> 0.047505304 | O14: 0.63497816 | P14: 0.67891244 | Q14: =(P14/O14)-1 -> 0.069190237
B15: Total Tickets per Visit | C15: 2.017865 | D15: 2.160692 | E15: =(D15/C15)-1 -> 0.070781247 | F15: 1.867902 | G15: 1.854179 | H15: =(G15/F15)-1 -> -0.0073467452 | I15: 0.821335 | J15: 1.147733 | K15: =(J15/I15)-1 -> 0.39739936 | L15: 1.761606 | M15: 1.932342 | N15: =(M15/L15)-1 -> 0.096920651 | O15: 1.807666 | P15: 1.949377 | Q15: =(P15/O15)-1 -> 0.07839446
B16: $9.99 Tickets per Visit (Member+Companion) | C16: - | D16: 1.334301 | E16: - | F16: - | G16: 1.295734 | H16: - | I16: - | J16: 0.789688 | K16: - | L16: - | M16: 1.258919 | N16: - | O16: - | P16: 1.277986 | Q16: -
B17: Uptake Premium Experiences | C17: 0.274127 | D17: 0.327918 | E17: =(D17/C17)-1 -> 0.19622657 | F17: 0.236614 | G17: 0.273039 | H17: =(G17/F17)-1 -> 0.15394271 | I17: 0.123656 | J17: 0.196785 | K17: =(J17/I17)-1 -> 0.59139063 | L17: 0.241173 | M17: 0.299438 | N17: =(M17/L17)-1 -> 0.24159006 | O17: 0.229338 | P17: 0.298772 | Q17: =(P17/O17)-1 -> 0.30275837
B18: Uptake Companion Experience | C18: - | D18: 0.954102 | E18: - | F18: - | G18: 0.5574 | H18: - | I18: - | J18: 0.744726 | K18: - | L18: - | M18: 0.765473 | N18: - | O18: - | P18: 0.733097 | Q18: -
B21: Cineclub Member who visited in both years (2019 and 2025) | C21: Champions | F21: Potential Loyalist | I21: Value Conscious Loyals | L21: Total Top 3 Segements | O21: Total All Cineclub Members
C22: 2019 | D22: 2025 | E22: % Change | F22: 2019 | G22: 2025 | H22: % Change | I22: 2019 | J22: 2025 | K22: % Change | L22: 2019 | M22: 2025 | N22: % Change | O22: 2019 | P22: 2025 | Q22: % Change
B23: No of Members | C23: 51246 | F23: 47464 | I23: 6673 | L23: 105383 | O23: 119397
B24: Avg Frequency | C24: 11.458006 | D24: 15.488702 | E24: =(D24/C24)-1 -> 0.35177979 | F24: 9.2387494 | G24: 10.632395 | H24: =(G24/F24)-1 -> 0.15084788 | I24: 13.806684 | J24: 20.612768 | K24: =(J24/I24)-1 -> 0.49295576 | L24: 10.607185 | M24: 13.625907 | N24: =(M24/L24)-1 -> 0.2845922 | O24: 10.021885 | P24: 12.305862 | Q24: =(P24/O24)-1 -> 0.22789894
B25: Avg Total Spend per visit | C25: 35.566111 | D25: 48.170691 | E25: =(D25/C25)-1 -> 0.3543986 | F25: 30.093135 | G25: 34.894474 | H25: =(G25/F25)-1 -> 0.15954931 | I25: 18.38728 | J25: 15.989916 | K25: =(J25/I25)-1 -> -0.13038166 | L25: 32.003217 | M25: 40.422203 | N25: =(M25/L25)-1 -> 0.26306687 | O25: 32.126107 | P25: 40.664961 | Q25: =(P25/O25)-1 -> 0.26579174
B26: Avg Ticket Spend per visit | C26: 21.348052 | D26: 27.555337 | E26: =(D26/C26)-1 -> 0.29076587 | F26: 19.166442 | G26: 21.967309 | H26: =(G26/F26)-1 -> 0.1461339 | I26: 13.809232 | J26: 12.051338 | K26: =(J26/I26)-1 -> -0.12729846 | L26: 19.870869 | M26: 24.106311 | N26: =(M26/L26)-1 -> 0.2131483 | O26: 19.965465 | P26: 24.280961 | Q26: =(P26/O26)-1 -> 0.21614803
B27: Avg Concession Spend per visit | C27: 14.218059 | D27: 20.615353 | E27: =(D27/C27)-1 -> 0.44994144 | F27: 10.926693 | G27: 12.927164 | H27: =(G27/F27)-1 -> 0.1830811 | I27: 4.578048 | J27: 3.938578 | K27: =(J27/I27)-1 -> -0.1396818 | L27: 12.132347 | M27: 16.315892 | N27: =(M27/L27)-1 -> 0.3448257 | O27: 12.160641 | P27: 16.384 | Q27: =(P27/O27)-1 -> 0.3472974
B28: Total Spend per person in a year | C28: 407.51673 | D28: 746.10145 | E28: =(D28/C28)-1 -> 0.83084864 | F28: 278.02294 | G28: 371.01183 | H28: =(G28/F28)-1 -> 0.33446483 | I28: 253.86736 | J28: 329.59643 | K28: =(J28/I28)-1 -> 0.2983017 | L28: 339.46405 | M28: 550.78919 | N28: =(M28/L28)-1 -> 0.62252584 | O28: 321.96414 | P28: 500.41739 | Q28: =(P28/O28)-1 -> 0.55426435
B29: Ticket Spend per person in a year | C29: 244.60612 | D29: 426.7964 | E29: =(D29/C29)-1 -> 0.74483121 | F29: 177.07396 | G29: 233.56511 | H29: =(G29/F29)-1 -> 0.31902577 | I29: 190.6597 | J29: 248.41144 | K29: =(J29/I29)-1 -> 0.3029048 | L29: 210.77399 | M29: 328.47036 | N29: =(M29/L29)-1 -> 0.55840081 | O29: 200.0916 | P29: 298.79815 | Q29: =(P29/O29)-1 -> 0.49330684
B30: Concession Spend per person in a year | C30: 162.91061 | D30: 319.30506 | E30: =(D30/C30)-1 -> 0.96000162 | F30: 100.94898 | G30: 137.44672 | H30: =(G30/F30)-1 -> 0.36154639 | I30: 63.207659 | J30: 81.184987 | K30: =(J30/I30)-1 -> 0.28441692 | L30: 128.69006 | M30: 222.31883 | N30: =(M30/L30)-1 -> 0.72755253 | O30: 121.87255 | P30: 201.61924 | Q30: =(P30/O30)-1 -> 0.654345
B31: Concession Incidence | C31: 0.68175865 | D31: 0.81080815 | E31: =(D31/C31)-1 -> 0.18928913 | F31: 0.60073704 | G31: 0.6684811 | H31: =(G31/F31)-1 -> 0.11276824 | I31: 0.38706421 | J31: 0.39627333 | K31: =(J31/I31)-1 -> 0.023792217 | L31: 0.6256856 | M31: 0.72107938 | N31: =(M31/L31)-1 -> 0.1524628 | O31: 0.62371269 | P31: 0.72017644 | Q31: =(P31/O31)-1 -> 0.15466056
B32: Total Tickets per Visit | C32: 1.968468 | D32: 2.15208 | E32: =(D32/C32)-1 -> 0.093276599 | F32: 1.81144 | G32: 1.826058 | H32: =(G32/F32)-1 -> 0.0080698229 | I32: 1.386304 | J32: 1.156206 | K32: =(J32/I32)-1 -> -0.16597947 | L32: 1.858885 | M32: 1.942105 | N32: =(M32/L32)-1 -> 0.044768773 | O32: 1.867796 | P32: 1.954327 | Q32: =(P32/O32)-1 -> 0.046327864
B36: NOT a Cineclub Member who visited in both years (2019 and 2025) | C36: Champions | F36: Potential Loyalist | I36: Value Conscious Loyals | L36: Total Top 3 Segements | O36: Total All Scene+ Members
C37: 2019 | D37: 2025 | E37: % Change | F37: 2019 | G37: 2025 | H37: % Change | I37: 2019 | J37: 2025 | K37: % Change | L37: 2019 | M37: 2025 | N37: % Change | O37: 2019 | P37: 2025 | Q37: % Change
B38: No of Members | C38: 98616 | F38: 330487 | I38: 40655 | L38: 469758 | O38: 1617212
B39: Avg Frequency | C39: 10.118662 | D39: 10.920652 | E39: =(D39/C39)-1 -> 0.079258455 | F39: 7.3976283 | G39: 5.8778137 | H39: =(G39/F39)-1 -> -0.20544621 | I39: 10.466462 | J39: 9.8882056 | K39: =(J39/I39)-1 -> -0.055248476 | L39: 8.2344441 | M39: 7.2835311 | N39: =(M39/L39)-1 -> -0.11547993 | O39: 5.8772282 | P39: 3.339585 | Q39: =(P39/O39)-1 -> -0.4317755
B40: Avg Total Spend per visit | C40: 35.471666 | D40: 51.829071 | E40: =(D40/C40)-1 -> 0.46114003 | F40: 32.051462 | G40: 44.584131 | H40: =(G40/F40)-1 -> 0.39101708 | I40: 17.445815 | J40: 14.507692 | K40: =(J40/I40)-1 -> -0.1684142 | L40: 31.327089 | M40: 43.330751 | N40: =(M40/L40)-1 -> 0.38317196 | O40: 31.422137 | P40: 44.224853 | Q40: =(P40/O40)-1 -> 0.40744256
B41: Avg Ticket Spend per visit | C41: 21.077123 | D41: 30.266403 | E41: =(D41/C41)-1 -> 0.4359836 | F41: 19.866827 | G41: 27.212014 | H41: =(G41/F41)-1 -> 0.36972119 | I41: 12.529021 | J41: 9.360813 | K41: =(J41/I41)-1 -> -0.25286956 | L41: 19.37186 | M41: 26.076007 | N41: =(M41/L41)-1 -> 0.34607658 | O41: 19.598378 | P41: 26.930608 | Q41: =(P41/O41)-1 -> 0.37412433
B42: Avg Concession Spend per visit | C42: 14.394543 | D42: 21.562668 | E42: =(D42/C42)-1 -> 0.49797517 | F42: 12.184635 | G42: 17.372117 | H42: =(G42/F42)-1 -> 0.42573963 | I42: 4.916794 | J42: 5.146879 | K42: =(J42/I42)-1 -> 0.046795737 | L42: 11.95523 | M42: 17.254745 | N42: =(M42/L42)-1 -> 0.44328005 | O42: 11.823759 | P42: 17.294244 | Q42: =(P42/O42)-1 -> 0.46266885
B43: Total Spend per person in a year | C43: 358.92581 | D43: 566.00724 | E43: =(D43/C43)-1 -> 0.57694772 | F43: 237.1048 | G43: 262.05721 | H43: =(G43/F43)-1 -> 0.10523789 | I43: 182.59595 | J43: 143.45504 | K43: =(J43/I43)-1 -> -0.21435806 | L43: 257.96117 | M43: 315.60088 | N43: =(M43/L43)-1 -> 0.22344336 | O43: 184.67507 | P43: 147.69266 | Q43: =(P43/O43)-1 -> -0.20025666
B44: Ticket Spend per person in a year | C44: 213.27229 | D44: 330.52884 | E44: =(D44/C44)-1 -> 0.54979746 | F44: 146.96741 | G44: 159.94715 | H44: =(G44/F44)-1 -> 0.088317134 | I44: 131.13452 | J44: 92.561644 | K44: =(J44/I44)-1 -> -0.29414737 | L44: 159.5165 | M44: 189.92541 | N44: =(M44/L44)-1 -> 0.19063175 | O44: 115.18414 | P44: 89.937057 | Q44: =(P44/O44)-1 -> -0.21918888
B45: Concession Spend per person in a year | C45: 145.65352 | D45: 235.47839 | E45: =(D45/C45)-1 -> 0.61670234 | F45: 90.137399 | G45: 102.11007 | H45: =(G45/F45)-1 -> 0.13282687 | I45: 51.461437 | J45: 50.893397 | K45: =(J45/I45)-1 -> -0.011038168 | L45: 98.44467 | M45: 125.67547 | N45: =(M45/L45)-1 -> 0.27661021 | O45: 69.49093 | P45: 57.7556 | Q45: =(P45/O45)-1 -> -0.16887571
B46: Concession Incidence | C46: 0.69097731 | D46: 0.7448779 | E46: =(D46/C46)-1 -> 0.078006311 | F46: 0.6283072 | G46: 0.65951298 | H46: =(G46/F46)-1 -> 0.04966644 | I46: 0.4026166 | J46: 0.4653375 | K46: =(J46/I46)-1 -> 0.15578318 | L46: 0.61964725 | M46: 0.66356802 | N46: =(M46/L46)-1 -> 0.07088029 | O46: 0.6067042 | P46: 0.64529181 | Q46: =(P46/O46)-1 -> 0.063602017
B47: Total Tickets per Visit | C47: 1.991061 | D47: 2.044024 | E47: =(D47/C47)-1 -> 0.02660039 | F47: 1.916749 | G47: 1.911941 | H47: =(G47/F47)-1 -> -0.002508414 | I47: 1.401378 | J47: 0.972453 | K47: =(J47/I47)-1 -> -0.30607374 | L47: 1.879227 | M47: 1.843131 | N47: =(M47/L47)-1 -> -0.019207898 | O47: 1.911832 | P47: 1.890951 | Q47: =(P47/O47)-1 -> -0.010921985

Sheet YoY 24vs25
C3: Champions | F3: Potential Loyalist | I3: Value Conscious Loyals | L3: Total Top 3 Segements | O3: Total All Scene+ Members | T3: Time Period - YoY 2024/25 (SignUp Behaviour) | U3: Program lovers | X3: Seasonal Goers | AA3: Samplers | AD3: One Time Subscribers
B4: Time Period - YoY 2024/25 (CC - NO) | C4: Is Not Cineclub | E4: % Change | F4: Is Not Cineclub | H4: % Change | I4: Is Not Cineclub | K4: % Change | L4: Is Not Cineclub | N4: % Change | O4: Is Not Cineclub | Q4: % Change | U4: 2024 | V4: 2025 | W4: % Change | X4: 2024 | Y4: 2025 | Z4: % Change | AA4: 2024 | AB4: 2025 | AC4: % Change | AD4: 2024 | AE4: 2025 | AF4: % Change
C5: 2024 | D5: 2025 | F5: 2024 | G5: 2025 | I5: 2024 | J5: 2025 | L5: 2024 | M5: 2025 | O5: 2024 | P5: 2025 | T5: No of Members | U5: 103928 | V5: 123833 | W5: =(V5/U5)-1 -> 0.19152683 | X5: 19810 | Y5: 17883 | Z5: =(Y5/X5)-1 -> -0.097274104 | AA5: 11244 | AB5: 14235 | AC5: =(AB5/AA5)-1 -> 0.26600854 | AD5: 6893 | AE5: 7154 | AF5: =(AE5/AD5)-1 -> 0.0378645
B6: No of Members | C6: 163664 | D6: 159430 | E6: - | F6: 642559 | G6: 613487 | H6: - | I6: 79849 | J6: 85775 | K6: - | L6: 886072 | M6: 858692 | N6: - | O6: 3734524 | P6: 3635558 | Q6: - | T6: Avg Frequency | U6: 11.694972 | V6: 11.787916 | W6: =(V6/U6)-1 -> 0.007947387 | X6: 6.2909137 | Y6: 6.7131354 | Z6: =(Y6/X6)-1 -> 0.067116117 | AA6: 9.3036286 | AB6: 9.3025641 | AC6: =(AB6/AA6)-1 -> -0.00011441765 | AD6: 3.81561 | AE6: 4.3554655 | AF6: =(AE6/AD6)-1 -> 0.14148601
B7: Avg Frequency | C7: 10.559622 | D7: 10.755084 | E7: =(D7/C7)-1 -> 0.018510282 | F7: 5.6866887 | G7: 5.782918 | H7: =(G7/F7)-1 -> 0.016921848 | I7: 9.4204812 | J7: 10.123987 | K7: =(J7/I7)-1 -> 0.074678353 | L7: 6.9232286 | M7: 7.1397113 | N7: =(M7/L7)-1 -> 0.031269044 | O7: 2.8923501 | P7: 2.941563 | Q7: =(P7/O7)-1 -> 0.017014846 | T7: Avg Total Spend per visit | U7: 40.165048 | V7: 39.543649 | W7: =(V7/U7)-1 -> -0.015471139 | X7: 40.569081 | Y7: 37.380729 | Z7: =(Y7/X7)-1 -> -0.078590687 | AA7: 38.41931 | AB7: 36.637735 | AC7: =(AB7/AA7)-1 -> -0.046371849 | AD7: 41.189877 | AE7: 38.055361 | AF7: =(AE7/AD7)-1 -> -0.07609919
B8: Avg Total Spend per visit | C8: 51.021932 | D8: 50.613065 | E8: =(D8/C8)-1 -> -0.0080135622 | F8: 43.151793 | G8: 42.870543 | H8: =(G8/F8)-1 -> -0.0065176995 | I8: 14.282694 | J8: 13.792513 | K8: =(J8/I8)-1 -> -0.03431994 | L8: 41.829042 | M8: 40.917302 | N8: =(M8/L8)-1 -> -0.021796828 | O8: 42.608893 | P8: 41.945338 | Q8: =(P8/O8)-1 -> -0.015573164 | T8: Avg Ticket Spend per visit | U8: 22.880368 | V8: 24.173957 | W8: =(V8/U8)-1 -> 0.056537066 | X8: 23.489704 | Y8: 24.099396 | Z8: =(Y8/X8)-1 -> 0.025955741 | AA8: 23.056527 | AB8: 24.168978 | AC8: =(AB8/AA8)-1 -> 0.048248854 | AD8: 25.134312 | AE8: 25.506546 | AF8: =(AE8/AD8)-1 -> 0.014809811
B9: Avg Ticket Spend per visit | C9: 30.241765 | D9: 29.841093 | E9: =(D9/C9)-1 -> -0.013248963 | F9: 27.095139 | G9: 26.408159 | H9: =(G9/F9)-1 -> -0.025354366 | I9: 9.182336 | J9: 8.01329 | K9: =(J9/I9)-1 -> -0.12731466 | L9: 25.785133 | M9: 24.762792 | N9: =(M9/L9)-1 -> -0.039648473 | O9: 26.440622 | P9: 25.475662 | Q9: =(P9/O9)-1 -> -0.036495364 | T9: Avg Concession Spend per visit | U9: 15.632427 | V9: 15.369692 | W9: =(V9/U9)-1 -> -0.016807037 | X9: 15.133559 | Y9: 13.281333 | Z9: =(Y9/X9)-1 -> -0.12239197 | AA9: 13.829648 | AB9: 12.468757 | AC9: =(AB9/AA9)-1 -> -0.098403849 | AD9: 13.929889 | AE9: 12.548814 | AF9: =(AE9/AD9)-1 -> -0.099144714
B10: Avg Concession Spend per visit | C10: 20.780167 | D10: 20.771971 | E10: =(D10/C10)-1 -> -0.00039443446 | F10: 16.056654 | G10: 16.462384 | H10: =(G10/F10)-1 -> 0.02526863 | I10: 5.1003582 | J10: 5.779224 | K10: =(J10/I10)-1 -> 0.13310159 | L10: 16.043909 | M10: 16.15451 | N10: =(M10/L10)-1 -> 0.0068936258 | O10: 16.168271 | P10: 16.469676 | Q10: =(P10/O10)-1 -> 0.018641748 | T10: Total Spend per person in a year | U10: 469.72909 | V10: 466.13721 | W10: =(V10/U10)-1 -> -0.0076467073 | X10: 255.21659 | Y10: 250.9419 | Z10: =(Y10/X10)-1 -> -0.016749271 | AA10: 357.43899 | AB10: 340.82488 | AC10: =(AB10/AA10)-1 -> -0.046480961 | AD10: 157.16451 | AE10: 165.74881 | AF10: =(AE10/AD10)-1 -> 0.054619848
B11: Total Spend per person in a year | C11: 538.77233 | D11: 544.34775 | E11: =(D11/C11)-1 -> 0.010348381 | F11: 245.39082 | G11: 247.91683 | H11: =(G11/F11)-1 -> 0.01029385 | I11: 134.54985 | J11: 139.63523 | K11: =(J11/I11)-1 -> 0.037795488 | L11: 289.59202 | M11: 292.13772 | N11: =(M11/L11)-1 -> 0.0087906513 | O11: 123.23984 | P11: 123.38486 | Q11: =(P11/O11)-1 -> 0.0011767027 | T11: Ticket Spend per person in a year | U11: 267.58526 | V11: 284.96058 | W11: =(V11/U11)-1 -> 0.064933775 | X11: 147.7717 | Y11: 161.78251 | Z11: =(Y11/X11)-1 -> 0.094813907 | AA11: 214.50936 | AB11: 224.83347 | AC11: =(AB11/AA11)-1 -> 0.048128916 | AD11: 95.902733 | AE11: 111.09288 | AF11: =(AE11/AD11)-1 -> 0.1583912
B12: Ticket Spend per person in a year | C12: 319.34161 | D12: 320.94346 | E12: =(D12/C12)-1 -> 0.0050160899 | F12: 154.08162 | G12: 152.71622 | H12: =(G12/F12)-1 -> -0.0088615762 | I12: 86.502023 | J12: 81.126444 | K12: =(J12/I12)-1 -> -0.062143971 | L12: 178.51637 | M12: 176.79919 | N12: =(M12/L12)-1 -> -0.0096191852 | O12: 76.475537 | P12: 74.938266 | Q12: =(P12/O12)-1 -> -0.020101474 | T12: Concession Spend per person in a year | U12: 182.82078 | V12: 181.17664 | W12: =(V12/U12)-1 -> -0.0089932221 | X12: 95.203914 | Y12: 89.159387 | Z12: =(Y12/X12)-1 -> -0.063490327 | AA12: 128.66591 | AB12: 115.99141 | AC12: =(AB12/AA12)-1 -> -0.098507008 | AD12: 53.151026 | AE12: 54.655928 | AF12: =(AE12/AD12)-1 -> 0.028313705
B13: Concession Spend per person in a year | C13: 219.43072 | D13: 223.40429 | E13: =(D13/C13)-1 -> 0.018108562 | F13: 91.309195 | G13: 95.200617 | H13: =(G13/F13)-1 -> 0.042618077 | I13: 48.047829 | J13: 58.508785 | K13: =(J13/I13)-1 -> 0.21771965 | L13: 111.07565 | M13: 115.33854 | N13: =(M13/L13)-1 -> 0.038378209 | O13: 46.764301 | P13: 48.446589 | Q13: =(P13/O13)-1 -> 0.035973758 | T13: Concession Incidence | U13: 0.70709581 | V13: 0.69238621 | W13: =(V13/U13)-1 -> -0.020802843 | X13: 0.65077875 | Y13: 0.60765841 | Z13: =(Y13/X13)-1 -> -0.066259596 | AA13: 0.62144154 | AB13: 0.57882376 | AC13: =(AB13/AA13)-1 -> -0.068578911 | AD13: 0.58583324 | AE13: 0.57254726 | AF13: =(AE13/AD13)-1 -> -0.022678776
B14: Concession Incidence | C14: 0.72877511 | D14: 0.72861981 | E14: =(D14/C14)-1 -> -0.00021309199 | F14: 0.62376777 | G14: 0.63693501 | H14: =(G14/F14)-1 -> 0.021109211 | I14: 0.47833202 | J14: 0.55221935 | K14: =(J14/I14)-1 -> 0.15446871 | L14: 0.63551738 | M14: 0.65057832 | N14: =(M14/L14)-1 -> 0.023698707 | O14: 0.61992718 | P14: 0.63497816 | Q14: =(P14/O14)-1 -> 0.024278627 | T14: Total Tickets per Visit | U14: 1.9870696 | V14: 1.9548486 | W14: =(V14/U14)-1 -> -0.016215364 | X14: 1.9620536 | Y14: 1.8386186 | Z14: =(Y14/X14)-1 -> -0.06291111 | AA14: 2.0182679 | AB14: 1.9606712 | AC14: =(AB14/AA14)-1 -> -0.028537671 | AD14: 2.1147485 | AE14: 1.9432588 | AF14: =(AE14/AD14)-1 -> -0.081092253
B15: Total Tickets per Visit | C15: 2.0805547 | D15: 2.017865 | E15: =(D15/C15)-1 -> -0.03013123 | F15: 1.941966 | G15: 1.867902 | H15: =(G15/F15)-1 -> -0.03813869 | I15: 0.92732805 | J15: 0.821335 | K15: =(J15/I15)-1 -> -0.11429942 | L15: 1.8565939 | M15: 1.761606 | N15: =(M15/L15)-1 -> -0.05116243 | O15: 1.8929881 | P15: 1.807666 | Q15: =(P15/O15)-1 -> -0.045072731 | T15: $9.99 Tickets per Visit (Member+Companion) | U15: 1.317251 | V15: 1.3642255 | W15: =(V15/U15)-1 -> 0.035660999 | X15: 0.8446274 | Y15: 0.86435765 | Z15: =(Y15/X15)-1 -> 0.023359711 | AA15: 1.1427588 | AB15: 1.2087644 | AC15: =(AB15/AA15)-1 -> 0.057759857 | AD15: 0.71445953 | AE15: 0.75859302 | AF15: =(AE15/AD15)-1 -> 0.061771864
B16: $9.99 Tickets per Visit (Member+Companion) | C16: - | D16: - | E16: - | F16: - | G16: - | H16: - | I16: - | J16: - | K16: - | L16: - | M16: - | N16: - | O16: - | P16: - | Q16: - | T16: Uptake Premium Experiences | U16: 0.29579646 | V16: 0.301066 | W16: =(V16/U16)-1 -> 0.017814765 | X16: 0.26154419 | Y16: 0.28432732 | Z16: =(Y16/X16)-1 -> 0.08711006 | AA16: 0.25769783 | AB16: 0.28173674 | AC16: =(AB16/AA16)-1 -> 0.093283331 | AD16: 0.23626393 | AE16: 0.27864575 | AF16: =(AE16/AD16)-1 -> 0.17938334
B17: Uptake Premium Experiences | C17: 0.2695612 | D17: 0.274127 | E17: =(D17/C17)-1 -> 0.016937905 | F17: 0.2255268 | G17: 0.236614 | H17: =(G17/F17)-1 -> 0.049161326 | I17: 0.10525825 | J17: 0.123656 | K17: =(J17/I17)-1 -> 0.17478674 | L17: 0.2320628 | M17: 0.241173 | N17: =(M17/L17)-1 -> 0.039257475 | O17: 0.22734762 | P17: 0.229338 | Q17: =(P17/O17)-1 -> 0.0087548032 | T17: Uptake Companion Experience | U17: 0.62166216 | V17: 0.68741256 | W17: =(V17/U17)-1 -> 0.10576548 | X17: 0.95716039 | Y17: 0.96212537 | Z17: =(Y17/X17)-1 -> 0.0051871956 | AA17: 0.90660287 | AB17: 1.0389142 | AC17: =(AB17/AA17)-1 -> 0.14594191 | AD17: 0.98762429 | AE17: 1.026318 | AF17: =(AE17/AD17)-1 -> 0.039178623
B18: Uptake Companion Experience | C18: - | D18: - | E18: - | F18: - | G18: - | H18: - | I18: - | J18: - | K18: - | L18: - | M18: - | N18: - | O18: - | P18: - | Q18: -
C21: Champions | F21: Potential Loyalist | I21: Value Conscious Loyals | L21: Total Top 3 Segements | O21: Total All Scene+ Members
B22: Time Period - YoY 2024/25 (CC - YES) | C22: Is Cineclub | E22: % Change | F22: Is Cineclub | H22: % Change | I22: Is Cineclub | K22: % Change | L22: Is Cineclub | N22: % Change | O22: Is Cineclub | Q22: % Change
C23: 2024 | D23: 2025 | F23: 2024 | G23: 2025 | I23: 2024 | J23: 2025 | L23: 2024 | M23: 2025 | O23: 2024 | P23: 2025
B24: No of Members | C24: 64244 | D24: 79346 | E24: =(D24/C24)-1 -> 0.23507254 | F24: 67845 | G24: 87485 | H24: =(G24/F24)-1 -> 0.28948338 | I24: 10312 | J24: 14678 | K24: =(J24/I24)-1 -> 0.42339022 | L24: 142401 | M24: 181509 | N24: =(M24/L24)-1 -> 0.2746329 | O24: 173439 | P24: 217835 | Q24: =(P24/O24)-1 -> 0.25597472
B25: Avg Frequency | C25: 14.607668 | D25: 14.95478 | E25: =(D25/C25)-1 -> 0.023762362 | F25: 9.5644631 | G25: 9.931051 | H25: =(G25/F25)-1 -> 0.038328123 | I25: 17.174845 | J25: 17.631285 | K25: =(J25/I25)-1 -> 0.026576081 | L25: 12.390805 | M25: 12.749847 | N25: =(M25/L25)-1 -> 0.02897651 | O25: 10.564262 | P25: 10.996695 | Q25: =(P25/O25)-1 -> 0.040933571
B26: Avg Total Spend per visit | C26: 47.802825 | D26: 47.386639 | E26: =(D26/C26)-1 -> -0.0087063021 | F26: 35.080056 | G26: 34.377079 | H26: =(G26/F26)-1 -> -0.020039219 | I26: 15.926294 | J26: 15.792556 | K26: =(J26/I26)-1 -> -0.0083972902 | L26: 39.924295 | M26: 38.969417 | N26: =(M26/L26)-1 -> -0.023917218 | O26: 40.188412 | P26: 39.245078 | Q26: =(P26/O26)-1 -> -0.023472778
B27: Avg Ticket Spend per visit | C27: 27.909631 | D27: 27.665523 | E27: =(D27/C27)-1 -> -0.0087463612 | F27: 22.69982 | G27: 22.353575 | H27: =(G27/F27)-1 -> -0.015253193 | I27: 12.254523 | J27: 12.184674 | K27: =(J27/I27)-1 -> -0.0056998661 | L27: 24.422292 | M27: 23.940092 | N27: =(M27/L27)-1 -> -0.019744244 | O27: 24.665059 | P27: 24.179378 | Q27: =(P27/O27)-1 -> -0.019691056
B28: Avg Concession Spend per visit | C28: 19.893194 | D28: 19.721116 | E28: =(D28/C28)-1 -> -0.0086501002 | F28: 12.380236 | G28: 12.023504 | H28: =(G28/F28)-1 -> -0.028814653 | I28: 3.6717706 | J28: 3.607882 | K28: =(J28/I28)-1 -> -0.017399935 | L28: 15.502003 | M28: 15.029324 | N28: =(M28/L28)-1 -> -0.030491504 | O28: 15.523353 | P28: 15.0657 | Q28: =(P28/O28)-1 -> -0.029481558
B29: Total Spend per person in a year | C29: 698.28778 | D29: 708.65677 | E29: =(D29/C29)-1 -> 0.014849168 | F29: 335.5219 | G29: 341.40052 | H29: =(G29/F29)-1 -> 0.017520832 | I29: 273.53162 | J29: 278.44306 | K29: =(J29/I29)-1 -> 0.017955641 | L29: 494.69415 | M29: 496.85411 | N29: =(M29/L29)-1 -> 0.0043662501 | O29: 424.5609 | P29: 431.56614 | Q29: =(P29/O29)-1 -> 0.016499958
B30: Ticket Spend per person in a year | C30: 407.69461 | D30: 413.73181 | E30: =(D30/C30)-1 -> 0.014808151 | F30: 217.11159 | G30: 221.9945 | H30: =(G30/F30)-1 -> 0.022490308 | I30: 210.46953 | J30: 214.83146 | K30: =(J30/I30)-1 -> 0.020724755 | L30: 302.61185 | M30: 305.23252 | N30: =(M30/L30)-1 -> 0.0086601635 | O30: 260.56814 | P30: 265.89324 | Q30: =(P30/O30)-1 -> 0.020436474
B31: Concession Spend per person in a year | C31: 290.59317 | D31: 294.92496 | E31: =(D31/C31)-1 -> 0.014906713 | F31: 118.41031 | G31: 119.40603 | H31: =(G31/F31)-1 -> 0.0084090343 | I31: 63.06209 | J31: 63.611596 | K31: =(J31/I31)-1 -> 0.0087137328 | L31: 192.0823 | M31: 191.62159 | N31: =(M31/L31)-1 -> -0.0023985017 | O31: 163.99276 | P31: 165.6729 | Q31: =(P31/O31)-1 -> 0.010245227
B32: Concession Incidence | C32: 0.80026107 | D32: 0.79147937 | E32: =(D32/C32)-1 -> -0.010973544 | F32: 0.64320289 | G32: 0.62721076 | H32: =(G32/F32)-1 -> -0.024863274 | I32: 0.36326063 | J32: 0.3593465 | K32: =(J32/I32)-1 -> -0.010774979 | L32: 0.69863749 | M32: 0.68148424 | N32: =(M32/L32)-1 -> -0.024552435 | O32: 0.69558167 | P32: 0.67891244 | Q32: =(P32/O32)-1 -> -0.023964445
B33: Total Tickets per Visit | C33: 2.1843551 | D33: 2.160692 | E33: =(D33/C33)-1 -> -0.010833008 | F33: 1.8797998 | G33: 1.854179 | H33: =(G33/F33)-1 -> -0.013629561 | I33: 1.1578763 | J33: 1.147733 | K33: =(J33/I33)-1 -> -0.0087602725 | L33: 1.9693193 | M33: 1.932342 | N33: =(M33/L33)-1 -> -0.01877668 | O33: 1.9868681 | P33: 1.949377 | Q33: =(P33/O33)-1 -> -0.018869443
B34: $9.99 Tickets per Visit (Member+Companion) | C34: 1.2608319 | D34: 1.334301 | E34: - | F34: 1.2432436 | G34: 1.295734 | H34: - | I34: 0.77548036 | J34: 0.789688 | K34: - | L34: 1.2056467 | M34: 1.258919 | N34: - | O34: 1.2234132 | P34: 1.277986 | Q34: -
B35: Uptake Premium Experiences | C35: 0.3187682 | D35: 0.327918 | E35: =(D35/C35)-1 -> 0.0287036 | F35: 0.26409325 | G35: 0.273039 | H35: =(G35/F35)-1 -> 0.033873461 | I35: 0.18002321 | J35: 0.196785 | K35: =(J35/I35)-1 -> 0.093109039 | L35: 0.29138673 | M35: 0.299438 | N35: =(M35/L35)-1 -> 0.027630861 | O35: 0.2908578 | P35: 0.298772 | Q35: =(P35/O35)-1 -> 0.027209847
B36: Uptake Companion Experience | C36: 0.83267558 | D36: 0.954102 | E36: - | F36: 0.51623283 | G36: 0.5574 | H36: - | I36: 0.7184845 | J36: 0.744726 | K36: - | L36: 0.69153952 | M36: 0.765473 | N36: - | O36: 0.66829283 | P36: 0.733097 | Q36: -
B39: Visitation Overlap with 2019 Incrementality Comparison 2024 vs 2025 (RFM Segments) | T39: Visitation Overlap with 2019 Incrementality Comparison 2024 vs 2025 (SignUp Behaviour)
B43: 2024 vs 2025 (CC MEMBER) | C43: Champions | F43: Potential Loyalist | I43: Value Conscious Loyals | L43: Total Top 3 Segements | O43: Total All Cineclub Members | T43: Cineclub Member who visited in both years (2019 and 2024/2025) | U43: Program Lovers | X43: Seasonal Goers | AA43: Samplers | AD43: One Time Subscribers
C44: 2024 | D44: 2025 | E44: % Change | F44: 2024 | G44: 2025 | H44: % Change | I44: 2024 | J44: 2025 | K44: % Change | L44: 2024 | M44: 2025 | N44: % Change | O44: 2024 | P44: 2025 | Q44: % Change | U44: 2024 | V44: 2025 | W44: % Change | X44: 2024 | Y44: 2025 | Z44: % Change | AA44: 2024 | AB44: 2025 | AC44: % Change | AD44: 2024 | AE44: 2025 | AF44: % Change
B45: No of Members | C45: 44918 | D45: 51246 | E45: =(D45/C45)-1 -> 0.14087893 | F45: 40202 | G45: 47464 | H45: =(G45/F45)-1 -> 0.18063778 | I45: 5296 | J45: 6673 | K45: =(J45/I45)-1 -> 0.26000755 | L45: 90416 | M45: 105383 | N45: =(M45/L45)-1 -> 0.16553486 | O45: 102568 | P45: 119397 | Q45: =(P45/O45)-1 -> 0.16407652 | T45: No of Members | U45: 79346 | V45: 84786 | W45: =(V45/U45)-1 -> 0.068560482 | X45: 14181 | Y45: 12581 | Z45: =(Y45/X45)-1 -> -0.11282702 | AA45: 8889 | AB45: 9511 | AC45: =(AB45/AA45)-1 -> 0.069974125 | AD45: 7015 | AE45: 6903 | AF45: =(AE45/AD45)-1 -> -0.015965788
B46: Avg Frequency | C46: 15.048422 | D46: 15.488702 | E46: =(D46/C46)-1 -> 0.029257553 | F46: 10.256928 | G46: 10.632395 | H46: =(G46/F46)-1 -> 0.036606241 | I46: 20.041541 | J46: 20.612768 | K46: =(J46/I46)-1 -> 0.028502154 | L46: 13.210427 | M46: 13.625907 | N46: =(M46/L46)-1 -> 0.031450916 | O46: 11.923885 | P46: 12.305862 | Q46: =(P46/O46)-1 -> 0.032034637 | T46: Avg Frequency | U46: 11.571321 | V46: 11.652973 | W46: =(V46/U46)-1 -> 0.0070564827 | X46: 6.5618786 | Y46: 6.6207774 | Z46: =(Y46/X46)-1 -> 0.0089759041 | AA46: 8.9258634 | AB46: 8.9157817 | AC46: =(AB46/AA46)-1 -> -0.001129493 | AD46: 3.9947256 | AE46: 4.3268144 | AF46: =(AE46/AD46)-1 -> 0.083131828
B47: Avg Total Spend per visit | C47: 48.42216 | D47: 48.170691 | E47: =(D47/C47)-1 -> -0.0051932554 | F47: 35.290298 | G47: 34.894474 | H47: =(G47/F47)-1 -> -0.011216228 | I47: 16.083522 | J47: 15.989916 | K47: =(J47/I47)-1 -> -0.0058199909 | L47: 41.015025 | M47: 40.422203 | N47: =(M47/L47)-1 -> -0.014453785 | O47: 41.240906 | P47: 40.664961 | Q47: =(P47/O47)-1 -> -0.01396538 | T47: Avg Total Spend per visit | U47: 41.097421 | V47: 40.864097 | W47: =(V47/U47)-1 -> -0.00567735 | X47: 41.965149 | Y47: 39.685637 | Z47: =(Y47/X47)-1 -> -0.054319165 | AA47: 39.171984 | AB47: 37.602964 | AC47: =(AB47/AA47)-1 -> -0.04005464 | AD47: 40.824998 | AE47: 38.636599 | AF47: =(AE47/AD47)-1 -> -0.053604388
B48: Avg Ticket Spend per visit | C48: 25.559829 | D48: 27.555337 | E48: =(D48/C48)-1 -> 0.078072028 | F48: 20.897405 | G48: 21.967309 | H48: =(G48/F48)-1 -> 0.05119796 | I48: 11.921019 | J48: 12.051338 | K48: =(J48/I48)-1 -> 0.010931841 | L48: 22.738267 | M48: 24.106311 | N48: =(M48/L48)-1 -> 0.060164814 | O48: 22.893569 | P48: 24.280961 | Q48: =(P48/O48)-1 -> 0.060601834 | T48: Avg Ticket Spend per visit | U48: 22.827274 | V48: 22.570198 | W48: =(V48/U48)-1 -> -0.011261811 | X48: 23.642817 | Y48: 22.94978 | Z48: =(Y48/X48)-1 -> -0.029312778 | AA48: 23.055508 | AB48: 22.632878 | AC48: =(AB48/AA48)-1 -> -0.018330958 | AD48: 24.558117 | AE48: 23.679116 | AF48: =(AE48/AD48)-1 -> -0.035792669
B49: Avg Concession Spend per visit | C49: 20.591638 | D49: 20.615353 | E49: =(D49/C49)-1 -> 0.0011516817 | F49: 13.031964 | G49: 12.927164 | H49: =(G49/F49)-1 -> -0.0080417705 | I49: 3.9114764 | J49: 3.938578 | K49: =(J49/I49)-1 -> 0.0069287516 | L49: 16.499611 | M49: 16.315892 | N49: =(M49/L49)-1 -> -0.011134739 | O49: 16.549138 | P49: 16.384 | Q49: =(P49/O49)-1 -> -0.0099786297 | T49: Avg Concession Spend per visit | U49: 16.529981 | V49: 16.616706 | W49: =(V49/U49)-1 -> 0.0052465146 | X49: 16.176695 | Y49: 14.664221 | Z49: =(Y49/X49)-1 -> -0.093497104 | AA49: 14.468598 | AB49: 13.318484 | AC49: =(AB49/AA49)-1 -> -0.07949033 | AD49: 14.004448 | AE49: 12.978193 | AF49: =(AE49/AD49)-1 -> -0.073280679
...

Sheet Summary by Signup behavior
A1: Program lovers | B1: Signed up only once and renewed 5 or more times without cancelling
A2: Seasonal goers | B2: Signed up only once and renewed between 1 and 4 times without cancelling
A3: Samplers | B3: Signed up 2 or more times (cancelled at least once), may or may not have renewed thereafter
A4: One time subscribers | B4: Signed up only once and cancelled
A9: Time Period - FY 2025 | B9: Segmentation of monthly plan members based on number of times they signed up for Cineclub
B10: Program lovers | C10: Seasonal goers | D10: Samplers | E10: One time subscribers
A11: No of Members | B11: 123833 (76%) | C11: 17883 (11%) | D11: 14235 (9%) | E11: 7154 (4%)
A12: Avg Frequency | B12: 11.787916 | C12: 6.7131354 | D12: 9.3025641 | E12: 4.3554655
A13: Avg Total Spend per visit | B13: 39.543649 | C13: 37.367371 | D13: 36.637735 | E13: 38.055361
A14: Avg Ticket Spend per visit | B14: 24.173957 | C14: 24.08584 | D14: 24.168978 | E14: 25.506546
A15: Avg Concession Spend per visit | B15: 15.369692 | C15: 13.281531 | D15: 12.468757 | E15: 12.548814
A16: Total Spend per person in a year | B16: 466.13721 | C16: 250.85222 | D16: 340.82488 | E16: 165.74881
A17: Ticket Spend per person in a year | B17: 284.96058 | C17: 161.69151 | D17: 224.83347 | E17: 111.09288
A18: Concession Spend per person in a year | B18: 181.17664 | C18: 89.160713 | D18: 115.99141 | E18: 54.655928
A19: Concession Incidence | B19: 0.69238621 | C19: 0.60766674 | D19: 0.57882376 | E19: 0.57254726
A20: Total Tickets per Visit | B20: 1.9548486 | C20: 1.8378273 | D20: 1.9606712 | E20: 1.9432588
A21: $9.99 Tickets per Visit (Member+Companion) | B21: 1.3642255 | C21: 0.86435765 | D21: 1.2087644 | E21: 0.75859302
A22: Uptake Premium Experiences | B22: 0.301066 | C22: 0.28442255 | D22: 0.28173674 | E22: 0.27864575
A23: Uptake Companion Experience | B23: 0.68741256 | C23: 0.96212537 | D23: 1.0389142 | E23: 1.026318
A28: Cineclub Member who visited in both years (2019 and 2024) | B28: Program Lovers | E28: Seasonal Goers | H28: Samplers | K28: One Time Subscribers
B29: 2019 | C29: 2025 | D29: % Change | E29: 2019 | F29: 2025 | G29: % Change | H29: 2019 | I29: 2025 | J29: % Change | K29: 2019 | L29: 2025 | M29: % Change
A30: No of Members | B30: 84786 | E30: 12581 | H30: 9511 | K30: 6903
A31: Avg Frequency | B31: 9.8746019 | C31: 11.652973 | D31: =(C31/B31)-1 -> 0.18009551 | E31: 7.0120022 | F31: 6.6207774 | G31: =(F31/E31)-1 -> -0.055793602 | H31: 7.5123541 | I31: 8.9157817 | J31: =(I31/H31)-1 -> 0.18681596 | K31: 6.0557729 | L31: 4.3268144 | M31: =(L31/K31)-1 -> -0.28550582
A32: Avg Total Spend per visit | B32: 32.190723 | C32: 40.864097 | D32: =(C32/B32)-1 -> 0.26943707 | E32: 29.93472 | F32: 39.685637 | G32: =(F32/E32)-1 -> 0.32573938 | H32: 28.842686 | I32: 37.602964 | J32: =(I32/H32)-1 -> 0.30372615 | K32: 27.997369 | L32: 38.636599 | M32: =(L32/K32)-1 -> 0.38000821
A33: Avg Ticket Spend per visit | B33: 18.753766 | C33: 22.570198 | D33: =(C33/B33)-1 -> 0.20350217 | E33: 18.438482 | F33: 22.94978 | G33: =(F33/E33)-1 -> 0.24466754 | H33: 18.730546 | I33: 22.632878 | J33: =(I33/H33)-1 -> 0.20834054 | K33: 18.679868 | L33: 23.679116 | M33: =(L33/K33)-1 -> 0.26762759
A34: Avg Concession Spend per visit | B34: 12.31847 | C34: 16.616706 | D34: =(C34/B34)-1 -> 0.34892612 | E34: 10.450579 | F34: 14.664221 | G34: =(F34/E34)-1 -> 0.40319699 | H34: 9.128346 | I34: 13.318484 | J34: =(I34/H34)-1 -> 0.45902489 | K34: 8.371713 | L34: 12.978193 | M34: =(L34/K34)-1 -> 0.55024342
A35: Total Spend per person in a year | B35: 317.87057 | C35: 476.18824 | D35: =(C35/B35)-1 -> 0.498057 | E35: 209.90232 | F35: 262.74977 | G35: =(F35/E35)-1 -> 0.25177159 | H35: 216.67647 | I35: 335.25982 | J35: =(I35/H35)-1 -> 0.54728301 | K35: 169.54571 | L35: 167.1734 | M35: =(L35/K35)-1 -> -0.013992168
A36: Ticket Spend per person in a year | B36: 185.18598 | C36: 263.00991 | D36: =(C36/B36)-1 -> 0.42024748 | E36: 129.29068 | F36: 151.94539 | G36: =(F36/E36)-1 -> 0.17522307 | H36: 140.7105 | I36: 201.7898 | J36: =(I36/H36)-1 -> 0.43407783 | K36: 113.12104 | L36: 102.45514 | M36: =(L36/K36)-1 -> -0.094287459
A37: Concession Spend per person in a year | B37: 121.63999 | C37: 193.63403 | D37: =(C37/B37)-1 -> 0.5918616 | E37: 73.279487 | F37: 97.088545 | G37: =(F37/E37)-1 -> 0.32490754 | H37: 68.575365 | I37: 118.7447 | J37: =(I37/H37)-1 -> 0.73159409 | K37: 50.697194 | L37: 56.154233 | M37: =(L37/K37)-1 -> 0.10763986
A38: Concession Incidence | B38: 0.63160334 | C38: 0.72684156 | D38: =(C38/B38)-1 -> 0.15078802 | E38: 0.56083792 | F38: 0.63819391 | G38: =(F38/E38)-1 -> 0.13792931 | H38: 0.51004899 | I38: 0.60977853 | J38: =(I38/H38)-1 -> 0.19552935 | K38: 0.48551539 | L38: 0.58557654 | M38: =(L38/K38)-1 -> 0.20609263
A39: Total Tickets per Visit | B39: 1.8554862 | C39: 1.9537656 | D39: =(C39/B39)-1 -> 0.052966926 | E39: 1.8310095 | F39: 1.8862851 | G39: =(F39/E39)-1 -> 0.030188548 | H39: 1.8706648 | I39: 1.9816505 | J39: =(I39/H39)-1 -> 0.059329555 | K39: 1.9039064 | L39: 1.9721776 | M39: =(L39/K39)-1 -> 0.035858464

Sheet Incremental Spend
B4: Ticket Spend per visit (2024)
C5: No of members | D5: 2019 | E5: 2024 Factoring Inflation | F5: 2024 Actual | G5: % Incremental Spend per Visit | H5: Incremental Visits | I5: Total Incremental Spend per Member | J5: Total Incremental Spend
B6: Champions | C6: 44918 | D6: 19.896849 | E6: 25.219838 | F6: 25.559829 | G6: 0.01348112 | H6: 3.1206198 | I6: 83.817862 | J6: 3764930.7
B7: Potential Loyalist | C7: 40202 | D7: 18.095658 | E7: 22.936775 | F7: 20.897405 | G7: -0.088912706 | H7: 0.80585543 | I7: -2.433953 | J7: -97849.78
B8: Value Conscious Loyals | C8: 5296 | D8: 12.881825 | E8: 16.32809 | F8: 11.921019 | G8: -0.26990732 | H8: 4.9439199 | I8: -7.5997228 | J8: -40248.132
B9: Total Top 3 Segements | C9: 90416 | D9: 18.646182 | E9: 23.634581 | F9: 22.738267 | G9: -0.037923819 | H9: 2.198195 | I9: 40.112733 | J9: 3626832.8
B10: Total All Cineclub Members | C10: 102568 | D10: 18.755447 | E10: 23.773078 | F10: 22.893569 | G10: -0.03699601 | H10: 1.5658197 | I10: 26.737191 | J10: 2742380.2
B14: Concession Spend per visit (2024)
C15: No of members | D15: 2019 | E15: 2024 Factoring Inflation | F15: 2024 Actual | G15: % Incremental Spend | H15: Incremental Visits | I15: Total Incremental Spend per Member | J15: Total Incremental Spend
B16: Champions | C16: 44918 | D16: 14.425412 | E16: 20.51933 | F16: 20.591638 | G16: 0.0035238928 | H16: 3.1206198 | I16: 65.121148 | J16: 2925111.7
B17: Potential Loyalist | C17: 40202 | D17: 10.862318 | E17: 15.451031 | F17: 13.031964 | G17: -0.15656345 | H17: 0.80585543 | I17: -12.360894 | J17: -496932.68
B18: Value Conscious Loyals | C18: 5296 | D18: 4.4407837 | E18: 6.3167627 | F18: 3.9114764 | G18: -0.38077833 | H18: 4.9439199 | I18: -16.976075 | J18: -89905.294
B19: Total Top 3 Segements | C19: 90416 | D19: 12.263933 | E19: 17.444749 | F19: 16.499611 | G19: -0.054178941 | H19: 2.198195 | I19: 25.861283 | J19: 2338273.7
B20: Total All Cineclub Members | C20: 102568 | D20: 12.27184 | E20: 17.455995 | F20: 16.549138 | G20: -0.051951069 | H20: 1.5658197 | I20: 16.519677 | J20: 1694390.2
B23: Calendar Year | C23: BPP - Paid Tickets | D23: CPP - Paid Tickets
B24: 2019 | C24: 10.139415 | D24: 6.826899
B25: 2023 | C25: 12.300888 | D25: 9.1182273
B26: 2024 | C26: 12.852006 | D26: 9.7108764
B27: 2025 | C27: 13.063945 | D27: 9.98
B28: Inflation Factor | C28: =(C27/C24)-1 -> 0.28843172 | D28: =(D27/D24)-1 -> 0.4618643
B31: No CineClub | D31: Tickets Sold
B32: Ticket Revenue | C32: 5.0270603e+08 | D32: 39299835
B33: Concession Revenue | C33: 3.8748756e+08
B35: All inclusive | D35: Tickets Sold
B36: Ticket Revenue | C36: 5.5313976e+08 | D36: 43573159 | E36: =C36/D36 -> 12.694507
B37: Concession Revenue | C37: 4.2209639e+08 | E37: =C37/D36 -> 9.6870734
B41: Ticket Spend per Visit (2025)
C42: No of members | D42: 2019 | E42: 2025 Factoring Inflation | F42: 2025 Actual | G42: % Incremental Spend per Visit | H42: Incremental Visits | I42: Total Incremental Spend per Member | J42: Total Incremental Spend
B43: Champions | C43: ='Summary by RFM'!C23 -> 51246 | D43: ='Summary by RFM'!C26 -> 21.348052 | E43: =D43*(1+$C$28) -> 27.505507 | F43: ='Summary by RFM'!D26 -> 27.555337 | G43: =(F43/E43)-1 -> 0.0018116246 | H43: =E63 -> 4.0306951 | I43: =(H43*F43)+(G43*E43*C63) -> 111.63811 | J43: =I43*C43 -> 5721006.6
B44: Potential Loyalist | C44: ='Summary by RFM'!F23 -> 47464 | D44: ='Summary by RFM'!F26 -> 19.166442 | E44: =D44*(1+$C$28) -> 24.694652 | F44: ='Summary by RFM'!G26 -> 21.967309 | G44: =(F44/E44)-1 -> -0.11044265 | H44: =E64 -> 1.3936457 | I44: =(H44*F44)+(G44*E44*C64) -> 5.4174092 | J44: =I44*C44 -> 257131.91
B45: Value Conscious Loyals | C45: ='Summary by RFM'!I23 -> 6673 | D45: ='Summary by RFM'!I26 -> 13.809232 | E45: =D45*(1+$C$28) -> 17.792253 | F45: ='Summary by RFM'!J26 -> 12.051338 | G45: =(F45/E45)-1 -> -0.32266373 | H45: =E65 -> 6.8060842 | I45: =(H45*F45)+(G45*E45*C65) -> 2.7594306 | J45: =I45*C45 -> 18413.68
B46: Total Top 3 Segements | C46: ='Summary by RFM'!L23 -> 105383 | D46: ='Summary by RFM'!L26 -> 19.870869 | E46: =D46*(1+$C$28) -> 25.602258 | F46: ='Summary by RFM'!M26 -> 24.106311 | G46: =(F46/E46)-1 -> -0.058430273 | H46: =E66 -> 3.0187222 | I46: =(H46*F46)+(G46*E46*C66) -> 56.90247 | J46: =I46*C46 -> 5996553
B47: Total All Cineclub Members | C47: ='Summary by RFM'!O23 -> 119397 | D47: ='Summary by RFM'!O26 -> 19.965465 | E47: =D47*(1+$C$28) -> 25.724138 | F47: ='Summary by RFM'!P26 -> 24.280961 | G47: =(F47/E47)-1 -> -0.05610207 | H47: =E67 -> 2.283977 | I47: =(H47*F47)+(G47*E47*C67) -> 40.993798 | J47: =I47*C47 -> 4894536.5
B51: Concession Spend per Visit (2025)
C52: No of members | D52: 2019 | E52: 2025 Factoring Inflation | F52: 2025 Actual | G52: % Incremental Spend | H52: Incremental Visits | I52: Total Incremental Spend per Member | J52: Total Incremental Spend
B53: Champions | C53: =C43 -> 51246 | D53: ='Summary by RFM'!C27 -> 14.218059 | E53: =D53*(1+$D$28) -> 20.784873 | F53: ='Summary by RFM'!D27 -> 20.615353 | G53: =(F53/E53)-1 -> -0.0081559252 | H53: =E63 -> 4.0306951 | I53: =(H53*F53)+(G53*E53*C63) -> 81.151842 | J53: =I53*C53 -> 4158707.3
B54: Potential Loyalist | C54: =C44 -> 47464 | D54: ='Summary by RFM'!F27 -> 10.926693 | E54: =D54*(1+$D$28) -> 15.973342 | F54: ='Summary by RFM'!G27 -> 12.927164 | G54: =(F54/E54)-1 -> -0.19070388 | H54: =E64 -> 1.3936457 | I54: =(H54*F54)+(G54*E54*C64) -> -10.126992 | J54: =I54*C54 -> -480667.56
B55: Value Conscious Loyals | C55: =C45 -> 6673 | D55: ='Summary by RFM'!I27 -> 4.578048 | E55: =D55*(1+$D$28) -> 6.6924849 | F55: ='Summary by RFM'!J27 -> 3.938578 | G55: =(F55/E55)-1 -> -0.41149244 | H55: =E65 -> 6.8060842 | I55: =(H55*F55)+(G55*E55*C65) -> -11.216028 | J55: =I55*C55 -> -74844.557
B56: Total Top 3 Segements | C56: =C46 -> 105383 | D56: ='Summary by RFM'!L27 -> 12.132347 | E56: =D56*(1+$D$28) -> 17.735845 | F56: ='Summary by RFM'!M27 -> 16.315892 | G56: =(F56/E56)-1 -> -0.080061196 | H56: =E66 -> 3.0187222 | I56: =(H56*F56)+(G56*E56*C66) -> 34.191441 | J56: =I56*C56 -> 3603196.6
B57: Total All Cineclub Members | C57: =C47 -> 119397 | D57: ='Summary by RFM'!O27 -> 12.160641 | E57: =D57*(1+$D$28) -> 17.777207 | F57: ='Summary by RFM'!P27 -> 16.384 | G57: =(F57/E57)-1 -> -0.078370407 | H57: =E67 -> 2.283977 | I57: =(H57*F57)+(G57*E57*C67) -> 23.458119 | J57: =I57*C57 -> 2800829.1
...
