Workbook

Sheet All Email Performance
A1: Email Name | B1: Audience | C1: Business Unit | D1: Send Date | E1: Sends | F1: Delivery Rate | G1: Overall Bounces | H1: Unique Opens | I1: Open Rate | J1: Unique Clicks | K1: CTR | L1: CTO | M1: Unsubscribes | N1: Unsubscribe Rate | O1: Reporting
A2: PDM Promo Gaming Offer Dartmouth | B2: SCENE | C2: LBE | D2: 44928 | E2: 13198 | F2: =(E2-G2)/E2 -> 0.99712078 | G2: 38 | H2: 5485 | I2: =H2/E2 -> 0.41559327 | J2: 299 | K2: =J2/E2 -> 0.022654948 | L2: =J2/H2 -> 0.054512306 | M2: 90 | N2: =M2/E2 -> 0.006819215 | O2: LBE
A3: PDM Promo Gaming Offer Brampton | B3: SCENE | C3: LBE | D3: 44928 | E3: 12645 | F3: =(E3-G3)/E3 -> 0.99596679 | G3: 51 | H3: 5245 | I3: =H3/E3 -> 0.41478845 | J3: 196 | K3: =J3/E3 -> 0.015500198 | L3: =J3/H3 -> 0.037368923 | M3: 64 | N3: =M3/E3 -> 0.005061289 | O3: LBE
A4: PDM Promo Gaming Offer Whitby | B4: SCENE | C4: LBE | D4: 44928 | E4: 11705 | F4: =(E4-G4)/E4 -> 0.99589919 | G4: 48 | H4: 4726 | I4: =H4/E4 -> 0.40375908 | J4: 265 | K4: =J4/E4 -> 0.022639897 | L4: =J4/H4 -> 0.056072789 | M4: 81 | N4: =M4/E4 -> 0.0069201196 | O4: LBE
A5: Tuesday Deals FR | B5: SCENE | C5: Theatrical | D5: 44929 | E5: 22244 | F5: =(E5-G5)/E5 -> 0.99878619 | G5: 27 | H5: 7887 | I5: =H5/E5 -> 0.35456752 | J5: 378 | K5: =J5/E5 -> 0.016993347 | L5: =J5/H5 -> 0.047926968 | M5: 19 | N5: =M5/E5 -> 0.00085416292 | O5: Theatrical
A6: Tuesday Deals EN | B6: SCENE | C6: Theatrical | D6: 44929 | E6: 194636 | F6: =(E6-G6)/E6 -> 0.99814526 | G6: 361 | H6: 69766 | I6: =H6/E6 -> 0.35844345 | J6: 1647 | K6: =J6/E6 -> 0.0084619495 | L6: =J6/H6 -> 0.023607488 | M6: 157 | N6: =M6/E6 -> 0.00080663392 | O6: Theatrical
A7: Tuesday Deals FR | B7: CONNECT | C7: Theatrical | D7: 44929 | E7: 17887 | F7: =(E7-G7)/E7 -> 0.99921731 | G7: 14 | H7: 6856 | I7: =H7/E7 -> 0.38329513 | J7: 224 | K7: =J7/E7 -> 0.012523061 | L7: =J7/H7 -> 0.032672112 | M7: 38 | N7: =M7/E7 -> 0.0021244479 | O7: Theatrical
A8: Tuesday Deals EN | B8: CONNECT | C8: Theatrical | D8: 44929 | E8: 354949 | F8: =(E8-G8)/E8 -> 0.99838287 | G8: 574 | H8: 141863 | I8: =H8/E8 -> 0.3996715 | J8: 2270 | K8: =J8/E8 -> 0.006395285 | L8: =J8/H8 -> 0.016001353 | M8: 606 | N8: =M8/E8 -> 0.0017072875 | O8: Theatrical
A9: Cast Pass | C9: Other | D9: 44930 | E9: 321 | F9: =(E9-G9)/E9 -> 1 | G9: 0 | H9: 108 | I9: =H9/E9 -> 0.3364486 | J9: 4 | K9: =J9/E9 -> 0.012461059 | L9: =J9/H9 -> 0.037037037 | M9: 0 | N9: =M9/E9 -> 0 | O9: Other
A10: Film Anticipation FR | B10: SCENE | C10: TARA | D10: 44931 | E10: 9491 | F10: =(E10-G10)/E10 -> 0.98672427 | G10: 126 | H10: 2942 | I10: =H10/E10 -> 0.30997787 | J10: 391 | K10: =J10/E10 -> 0.041196923 | L10: =J10/H10 -> 0.13290279 | M10: 17 | N10: =M10/E10 -> 0.0017911706 | O10: Survey
A11: Film Anticipation EN | B11: SCENE | C11: TARA | D11: 44931 | E11: 85400 | F11: =(E11-G11)/E11 -> 0.97702576 | G11: 1962 | H11: 30869 | I11: =H11/E11 -> 0.3614637 | J11: 3607 | K11: =J11/E11 -> 0.042236534 | L11: =J11/H11 -> 0.11684862 | M11: 336 | N11: =M11/E11 -> 0.0039344262 | O11: Survey
A12: Employee Pincode | C12: Other | D12: 44931 | E12: 1678 | F12: =(E12-G12)/E12 -> 0.9988081 | G12: 2 | H12: 591 | I12: =H12/E12 -> 0.35220501 | J12: 23 | K12: =J12/E12 -> 0.013706794 | L12: =J12/H12 -> 0.03891709 | M12: 0 | N12: =M12/E12 -> 0 | O12: Other
A13: Friday What's On FR | B13: SCENE | C13: Theatrical | D13: 44932 | E13: 95994 | F13: =(E13-G13)/E13 -> 0.99888535 | G13: 107 | H13: 30775 | I13: =H13/E13 -> 0.32059295 | J13: 946 | K13: =J13/E13 -> 0.0098547826 | L13: =J13/H13 -> 0.030739236 | M13: 86 | N13: =M13/E13 -> 0.00089588933 | O13: Theatrical
A14: Friday What's On EN | B14: SCENE | C14: Theatrical | D14: 44932 | E14: 1750473 | F14: =(E14-G14)/E14 -> 0.99671403 | G14: 5752 | H14: 625509 | I14: =H14/E14 -> 0.35733713 | J14: 12915 | K14: =J14/E14 -> 0.0073780058 | L14: =J14/H14 -> 0.020647185 | M14: 2797 | N14: =M14/E14 -> 0.0015978538 | O14: Theatrical
A15: Friday What's On FR | B15: CONNECT | C15: Theatrical | D15: 44932 | E15: 223652 | F15: =(E15-G15)/E15 -> 0.99710711 | G15: 647 | H15: 78135 | I15: =H15/E15 -> 0.34935972 | J15: 3430 | K15: =J15/E15 -> 0.015336326 | L15: =J15/H15 -> 0.043898381 | M15: 1896 | N15: =M15/E15 -> 0.008477456 | O15: Theatrical
A16: Friday What's On EN | B16: CONNECT | C16: Theatrical | D16: 44932 | E16: 2511131 | F16: =(E16-G16)/E16 -> 0.99525075 | G16: 11926 | H16: 923449 | I16: =H16/E16 -> 0.36774226 | J16: 23859 | K16: =J16/E16 -> 0.0095012964 | L16: =J16/H16 -> 0.025836836 | M16: 11684 | N16: =M16/E16 -> 0.0046528835 | O16: Theatrical
A17: Edmonton Closure EN | B17: SCENE | C17: Theatrical | D17: 44932 | E17: 4172 | F17: =(E17-G17)/E17 -> 0.99856184 | G17: 6 | H17: 1614 | I17: =H17/E17 -> 0.38686481 | J17: 24 | K17: =J17/E17 -> 0.0057526366 | L17: =J17/H17 -> 0.014869888 | M17: 4 | N17: =M17/E17 -> 0.00095877277 | O17: Theatrical
A18: Edmonton Closure EN | B18: CONNECT | C18: Theatrical | D18: 44932 | E18: 2196 | F18: =(E18-G18)/E18 -> 0.99908925 | G18: 2 | H18: 865 | I18: =H18/E18 -> 0.393898 | J18: 15 | K18: =J18/E18 -> 0.0068306011 | L18: =J18/H18 -> 0.01734104 | M18: 4 | N18: =M18/E18 -> 0.0018214936 | O18: Theatrical
A19: Movie Guide EN 24MT | B19: CONNECT | C19: Store | D19: 44932 | E19: 229503 | F19: =(E19-G19)/E19 -> 0.99866233 | G19: 307 | H19: 105460 | I19: =H19/E19 -> 0.45951469 | J19: 2616 | K19: =J19/E19 -> 0.011398544 | L19: =J19/H19 -> 0.024805614 | M19: 317 | N19: =M19/E19 -> 0.0013812456 | O19: Store
A20: Movie Guide EN | B20: CONNECT | C20: Store | D20: 44932 | E20: 327320 | F20: =(E20-G20)/E20 -> 0.9971618 | G20: 929 | H20: 123722 | I20: =H20/E20 -> 0.37798485 | J20: 3484 | K20: =J20/E20 -> 0.010644018 | L20: =J20/H20 -> 0.028159907 | M20: 473 | N20: =M20/E20 -> 0.001445069 | O20: Store
A21: Movie Guide FR | B21: CONNECT | C21: Store | D21: 44933 | E21: 13458 | F21: =(E21-G21)/E21 -> 0.99903403 | G21: 13 | H21: 4436 | I21: =H21/E21 -> 0.32961807 | J21: 200 | K21: =J21/E21 -> 0.014861049 | L21: =J21/H21 -> 0.045085663 | M21: 42 | N21: =M21/E21 -> 0.0031208203 | O21: Store
A22: Arts & Culture Newsletter FR | B22: SCENE | C22: Theatrical | D22: 44933 | E22: 1320 | F22: =(E22-G22)/E22 -> 0.99848485 | G22: 2 | H22: 655 | I22: =H22/E22 -> 0.49621212 | J22: 100 | K22: =J22/E22 -> 0.075757576 | L22: =J22/H22 -> 0.15267176 | M22: 4 | N22: =M22/E22 -> 0.003030303 | O22: Theatrical
A23: Arts & Culture Newsletter EN | B23: SCENE | C23: Theatrical | D23: 44933 | E23: 10010 | F23: =(E23-G23)/E23 -> 0.9989011 | G23: 11 | H23: 4668 | I23: =H23/E23 -> 0.46633367 | J23: 555 | K23: =J23/E23 -> 0.055444555 | L23: =J23/H23 -> 0.1188946 | M23: 7 | N23: =M23/E23 -> 0.0006993007 | O23: Theatrical
A24: Arts & Culture Newsletter FR | B24: CONNECT | C24: Theatrical | D24: 44933 | E24: 571 | F24: =(E24-G24)/E24 -> 0.99649737 | G24: 2 | H24: 268 | I24: =H24/E24 -> 0.46935201 | J24: 18 | K24: =J24/E24 -> 0.031523643 | L24: =J24/H24 -> 0.067164179 | M24: 4 | N24: =M24/E24 -> 0.0070052539 | O24: Theatrical
... A37: Puss In Boots EN | B37: SCENE | C37: Store | D37: 44936 | E37: 169230 | F37: =(E37-G37)/E37 -> 0.99881818 | G37: 200 | H37: 74958 | I37: =H37/E37 -> 0.44293565 | J37: 970 | K37: =J37/E37 -> 0.0057318442 | L37: =J37/H37 -> 0.01294058 | M37: 184 | N37: =M37/E37 -> 0.0010872777 | O37: Store
A38: Employee Pincode | C38: Other | D38: 44938 | E38: 1672 | F38: =(E38-G38)/E38 -> 1 | G38: 0 | H38: 601 | I38: =H38/E38 -> 0.35944976 | J38: 18 | K38: =J38/E38 -> 0.01076555 | L38: =J38/H38 -> 0.029950083 | M38: 0 | N38: =M38/E38 -> 0 | O38: Other
A39: BTS Yet To Come FR | B39: CONNECT | C39: Theatrical | D39: 44938 | E39: 33268 | F39: =(E39-G39)/E39 -> 0.99819647 | G39: 60 | H39: 10310 | I39: =H39/E39 -> 0.30990742 | J39: 198 | K39: =J39/E39 -> 0.0059516653 | L39: =J39/H39 -> 0.019204656 | M39: 161 | N39: =M39/E39 -> 0.0048394854 | O39: Theatrical
A40: BTS Yet To Come FR | B40: SCENE | C40: Theatrical | D40: 44938 | E40: 57823 | F40: =(E40-G40)/E40 -> 0.99915259 | G40: 49 | H40: 15025 | I40: =H40/E40 -> 0.2598447 | J40: 136 | K40: =J40/E40 -> 0.0023520053 | L40: =J40/H40 -> 0.0090515807 | M40: 31 | N40: =M40/E40 -> 0.00053611885 | O40: Theatrical
A41: BTS Yet To Come EN | B41: CONNECT | C41: Theatrical | D41: 44938 | E41: 503909 | F41: =(E41-G41)/E41 -> 0.99717409 | G41: 1424 | H41: 185312 | I41: =H41/E41 -> 0.36774894 | J41: 2675 | K41: =J41/E41 -> 0.0053084982 | L41: =J41/H41 -> 0.014435115 | M41: 1796 | N41: =M41/E41 -> 0.0035641356 | O41: Theatrical
A42: BTS Yet To Come EN | B42: SCENE | C42: Theatrical | D42: 44938 | E42: 933758 | F42: =(E42-G42)/E42 -> 0.99778744 | G42: 2066 | H42: 328255 | I42: =H42/E42 -> 0.35154183 | J42: 3131 | K42: =J42/E42 -> 0.0033531172 | L42: =J42/H42 -> 0.0095383162 | M42: 1083 | N42: =M42/E42 -> 0.0011598294 | O42: Theatrical
A43: Friday What's On FR | B43: SCENE | C43: Theatrical | D43: 44939 | E43: 96595 | F43: =(E43-G43)/E43 -> 0.99883017 | G43: 113 | H43: 31810 | I43: =H43/E43 -> 0.32931311 | J43: 847 | K43: =J43/E43 -> 0.0087685698 | L43: =J43/H43 -> 0.026626847 | M43: 78 | N43: =M43/E43 -> 0.00080749521 | O43: Theatrical
A44: Friday What's On FR | B44: CONNECT | C44: Theatrical | D44: 44939 | E44: 226314 | F44: =(E44-G44)/E44 -> 0.99721184 | G44: 631 | H44: 81138 | I44: =H44/E44 -> 0.35851958 | J44: 2838 | K44: =J44/E44 -> 0.012540099 | L44: =J44/H44 -> 0.034977446 | M44: 1339 | N44: =M44/E44 -> 0.0059165584 | O44: Theatrical
A45: Friday What's On EN | B45: SCENE | C45: Theatrical | D45: 44939 | E45: 1768850 | F45: =(E45-G45)/E45 -> 0.99685219 | G45: 5568 | H45: 643388 | I45: =H45/E45 -> 0.36373237 | J45: 11627 | K45: =J45/E45 -> 0.0065731973 | L45: =J45/H45 -> 0.018071521 | M45: 2397 | N45: =M45/E45 -> 0.0013551177 | O45: Theatrical
A46: Friday What's On EN | B46: CONNECT | C46: Theatrical | D46: 44939 | E46: 2523494 | F46: =(E46-G46)/E46 -> 0.99528154 | G46: 11907 | H46: 918692 | I46: =H46/E46 -> 0.36405555 | J46: 20283 | K46: =J46/E46 -> 0.0080376652 | L46: =J46/H46 -> 0.022078128 | M46: 9972 | N46: =M46/E46 -> 0.0039516638 | O46: Theatrical
A47: Movie Guide EN 24MT | B47: CONNECT | C47: Store | D47: 44939 | E47: 252620 | F47: =(E47-G47)/E47 -> 0.99887974 | G47: 283 | H47: 95330 | I47: =H47/E47 -> 0.37736521 | J47: 2226 | K47: =J47/E47 -> 0.0088116539 | L47: =J47/H47 -> 0.023350467 | M47: 330 | N47: =M47/E47 -> 0.0013063099 | O47: Store
A48: Movie Guide EN | B48: CONNECT | C48: Store | D48: 44939 | E48: 334315 | F48: =(E48-G48)/E48 -> 0.99789121 | G48: 705 | H48: 101194 | I48: =H48/E48 -> 0.30269058 | J48: 2570 | K48: =J48/E48 -> 0.0076873607 | L48: =J48/H48 -> 0.025396763 | M48: 321 | N48: =M48/E48 -> 0.00096017229 | O48: Store
A49: Adv Tickets Ant Man Quantumania FR | B49: SCENE | C49: Theatrical | D49: 44942 | E49: 117955 | F49: =(E49-G49)/E49 -> 0.99886397 | G49: 134 | H49: 42090 | I49: =H49/E49 -> 0.35683099 | J49: 693 | K49: =J49/E49 -> 0.0058751219 | L49: =J49/H49 -> 0.016464718 | M49: 104 | N49: =M49/E49 -> 0.00088169217 | O49: Theatrical
A50: Adv Tickets Ant Man Quantumania FR | B50: CONNECT | C50: Theatrical | D50: 44942 | E50: 227708 | F50: =(E50-G50)/E50 -> 0.99702689 | G50: 677 | H50: 86575 | I50: =H50/E50 -> 0.38020184 | J50: 2769 | K50: =J50/E50 -> 0.012160311 | L50: =J50/H50 -> 0.031983829 | M50: 2077 | N50: =M50/E50 -> 0.0091213308 | O50: Theatrical
... A60: Pathaan Primary Audience EN | B60: SCENE | C60: Theatrical | D60: 44944 | E60: 288246 | F60: =(E60-G60)/E60 -> 0.99808844 | G60: 551 | H60: 170575 | I60: =H60/E60 -> 0.59176884 | J60: 4871 | K60: =J60/E60 -> 0.01689876 | L60: =J60/H60 -> 0.028556354 | M60: 276 | N60: =M60/E60 -> 0.00095751546 | O60: Theatrical
A61: Cast Pass | C61: Other | D61: 44944 | E61: 315 | F61: =(E61-G61)/E61 -> 1 | G61: 0 | H61: 82 | I61: =H61/E61 -> 0.26031746 | J61: 7 | K61: =J61/E61 -> 0.022222222 | L61: =J61/H61 -> 0.085365854 | M61: 0 | N61: =M61/E61 -> 0 | O61: Other
...

Sheet Consolidated View
A1: Email Name | B1: Business Unit | C1: Send Date | D1: Sends | E1: Delivery Rate | F1: Overall Bounces | G1: Unique Opens | H1: Open Rate | I1: Unique Clicks | J1: CTR | K1: CTO | L1: Unsubscribes | M1: Unsubscribe Rate | N1: Reporting
A2: PDM Promo Gaming Offer Dartmouth | B2: LBE | C2: 44928 | D2: 13198 | E2: =(D2-F2)/D2 -> 0.99712078 | F2: 38 | G2: 5485 | H2: =G2/D2 -> 0.41559327 | I2: 299 | J2: =I2/D2 -> 0.022654948 | K2: =I2/G2 -> 0.054512306 | L2: 90 | M2: =L2/D2 -> 0.006819215 | N2: LBE
A3: PDM Promo Gaming Offer Brampton | B3: LBE | C3: 44928 | D3: 12645 | E3: =(D3-F3)/D3 -> 0.99596679 | F3: 51 | G3: 5245 | H3: =G3/D3 -> 0.41478845 | I3: 196 | J3: =I3/D3 -> 0.015500198 | K3: =I3/G3 -> 0.037368923 | L3: 64 | M3: =L3/D3 -> 0.005061289 | N3: LBE
A4: PDM Promo Gaming Offer Whitby | B4: LBE | C4: 44928 | D4: 11705 | E4: =(D4-F4)/D4 -> 0.99589919 | F4: 48 | G4: 4726 | H4: =G4/D4 -> 0.40375908 | I4: 265 | J4: =I4/D4 -> 0.022639897 | K4: =I4/G4 -> 0.056072789 | L4: 81 | M4: =L4/D4 -> 0.0069201196 | N4: LBE
A5: Tuesday Deals EN | B5: Theatrical | C5: 44929 | D5: 549585 | E5: =(D5-F5)/D5 -> 0.99829872 | F5: 935 | G5: 211629 | H5: =G5/D5 -> 0.38507055 | I5: 3917 | J5: =I5/D5 -> 0.007127196 | K5: =I5/G5 -> 0.018508806 | L5: 763 | M5: =L5/D5 -> 0.0013883203 | N5: Theatrical
A6: Tuesday Deals FR | B6: Theatrical | C6: 44929 | D6: 40131 | E6: =(D6-F6)/D6 -> 0.99897835 | F6: 41 | G6: 14743 | H6: =G6/D6 -> 0.36737186 | I6: 602 | J6: =I6/D6 -> 0.015000872 | K6: =I6/G6 -> 0.040832938 | L6: 57 | M6: =L6/D6 -> 0.0014203484 | N6: Theatrical
A7: Cast Pass | B7: Other | C7: 44930 | D7: 321 | E7: =(D7-F7)/D7 -> 1 | F7: 0 | G7: 108 | H7: =G7/D7 -> 0.3364486 | I7: 4 | J7: =I7/D7 -> 0.012461059 | K7: =I7/G7 -> 0.037037037 | L7: 0 | M7: =L7/D7 -> 0 | N7: Other
A8: Employee Pincode | B8: Other | C8: 44931 | D8: 1678 | E8: =(D8-F8)/D8 -> 0.9988081 | F8: 2 | G8: 591 | H8: =G8/D8 -> 0.35220501 | I8: 23 | J8: =I8/D8 -> 0.013706794 | K8: =I8/G8 -> 0.03891709 | L8: 0 | M8: =L8/D8 -> 0 | N8: Other
A9: Film Anticipation EN | B9: TARA | C9: 44931 | D9: 85400 | E9: =(D9-F9)/D9 -> 0.97702576 | F9: 1962 | G9: 30869 | H9: =G9/D9 -> 0.3614637 | I9: 3607 | J9: =I9/D9 -> 0.042236534 | K9: =I9/G9 -> 0.11684862 | L9: 336 | M9: =L9/D9 -> 0.0039344262 | N9: Survey
A10: Film Anticipation FR | B10: TARA | C10: 44931 | D10: 9491 | E10: =(D10-F10)/D10 -> 0.98672427 | F10: 126 | G10: 2942 | H10: =G10/D10 -> 0.30997787 | I10: 391 | J10: =I10/D10 -> 0.041196923 | K10: =I10/G10 -> 0.13290279 | L10: 17 | M10: =L10/D10 -> 0.0017911706 | N10: Survey
A11: Edmonton Closure EN | B11: Theatrical | C11: 44932 | D11: 6368 | E11: =(D11-F11)/D11 -> 0.99874372 | F11: 8 | G11: 2479 | H11: =G11/D11 -> 0.3892902 | I11: 39 | J11: =I11/D11 -> 0.0061243719 | K11: =I11/G11 -> 0.01573215 | L11: 8 | M11: =L11/D11 -> 0.0012562814 | N11: Theatrical
A12: Friday What's On EN | B12: Theatrical | C12: 44932 | D12: 4261604 | E12: =(D12-F12)/D12 -> 0.9958518 | F12: 17678 | G12: 1548958 | H12: =G12/D12 -> 0.36346831 | I12: 36774 | J12: =I12/D12 -> 0.0086291453 | K12: =I12/G12 -> 0.023741121 | L12: 14481 | M12: =L12/D12 -> 0.0033980163 | N12: Theatrical
A13: Friday What's On FR | B13: Theatrical | C13: 44932 | D13: 319646 | E13: =(D13-F13)/D13 -> 0.99764114 | F13: 754 | G13: 108910 | H13: =G13/D13 -> 0.34072067 | I13: 4376 | J13: =I13/D13 -> 0.013690145 | K13: =I13/G13 -> 0.040179965 | L13: 1982 | M13: =L13/D13 -> 0.0062006094 | N13: Theatrical
... A15: Movie Guide EN 24MT | B15: Store | C15: 44932 | D15: 229503 | E15: =(D15-F15)/D15 -> 0.99866233 | F15: 307 | G15: 105460 | H15: =G15/D15 -> 0.45951469 | I15: 2616 | J15: =I15/D15 -> 0.011398544 | K15: =I15/G15 -> 0.024805614 | L15: 317 | M15: =L15/D15 -> 0.0013812456 | N15: Store
A16: Movie Guide FR | C16: 44933 | D16: ='All Email Performance'!E21 -> 13458 | E16: =(D16-F16)/D16 -> 0.99903403 | F16: ='All Email Performance'!G21 -> 13 | G16: ='All Email Performance'!H21 -> 4436 | H16: =G16/D16 -> 0.32961807 | I16: ='All Email Performance'!J21 -> 200 | J16: =I16/D16 -> 0.014861049 | K16: =I16/G16 -> 0.045085663 | L16: ='All Email Performance'!M21 -> 42 | M16: =L16/D16 -> 0.0031208203 | N16: Store
A17: Arts & Culture Newsletter EN | B17: Theatrical | C17: 44933 | D17: 17329 | E17: =(D17-F17)/D17 -> 0.99878816 | F17: 21 | G17: 8094 | H17: =G17/D17 -> 0.46707831 | I17: 858 | J17: =I17/D17 -> 0.049512378 | K17: =I17/G17 -> 0.10600445 | L17: 28 | M17: =L17/D17 -> 0.0016157886 | N17: Theatrical
A18: Arts & Culture Newsletter FR | B18: Theatrical | C18: 44933 | D18: 1891 | E18: =(D18-F18)/D18 -> 0.99788472 | F18: 4 | G18: 923 | H18: =G18/D18 -> 0.48810153 | I18: 118 | J18: =I18/D18 -> 0.062400846 | K18: =I18/G18 -> 0.12784399 | L18: 8 | M18: =L18/D18 -> 0.0042305658 | N18: Theatrical
A19: Adv Tickets Plane FR | B19: Theatrical | C19: 44935 | D19: =SUM('All Email Performance'!E26:E27) -> 186248 | E19: =(D19-F19)/D19 -> 0.99895301 | F19: =SUM('All Email Performance'!G26:G27) -> 195 | G19: =SUM('All Email Performance'!H26:H27) -> 67718 | H19: =G19/D19 -> 0.36359048 | I19: =SUM('All Email Performance'!J26:J27) -> 1416 | J19: =I19/D19 -> 0.0076027662 | K19: =I19/G19 -> 0.020910245 | L19: =SUM('All Email Performance'!M26:M27) -> 811 | M19: =L19/D19 -> 0.0043544092 | N19: Theatrical
A20: Adv Tickets Plane EN | B20: Theatrical | C20: 44935 | D20: =SUM('All Email Performance'!E28:E29) -> 2643844 | E20: =(D20-F20)/D20 -> 0.99806683 | F20: =SUM('All Email Performance'!G28:G29) -> 5111 | G20: =SUM('All Email Performance'!H28:H29) -> 1028904 | H20: =G20/D20 -> 0.38916971 | I20: =SUM('All Email Performance'!J28:J29) -> 14390 | J20: =I20/D20 -> 0.0054428325 | K20: =I20/G20 -> 0.013985756 | L20: =SUM('All Email Performance'!M28:M29) -> 6305 | M20: =L20/D20 -> 0.0023847852 | N20: Theatrical
A21: Tuesday Deals FR | B21: Theatrical | C21: 44936 | D21: =SUM('All Email Performance'!E30:E31) -> 40844 | E21: =(D21-F21)/D21 -> 0.99933895 | F21: =SUM('All Email Performance'!G30:G31) -> 27 | G21: =SUM('All Email Performance'!H30:H31) -> 15322 | H21: =G21/D21 -> 0.37513466 | I21: =SUM('All Email Performance'!J30:J31) -> 580 | J21: =I21/D21 -> 0.014200372 | K21: =I21/G21 -> 0.037854066 | L21: =SUM('All Email Performance'!M30:M31) -> 47 | M21: =L21/D21 -> 0.0011507198 | N21: Theatrical
A22: Tuesday Deals EN | B22: Theatrical | C22: 44936 | D22: =SUM('All Email Performance'!E32:E33) -> 554909 | E22: =(D22-F22)/D22 -> 0.99850606 | F22: =SUM('All Email Performance'!G32:G33) -> 829 | G22: =SUM('All Email Performance'!H32:H33) -> 213766 | H22: =G22/D22 -> 0.38522713 | I22: =SUM('All Email Performance'!J32:J33) -> 4220 | J22: =I22/D22 -> 0.0076048505 | K22: =I22/G22 -> 0.019741212 | L22: =SUM('All Email Performance'!M32:M33) -> 679 | M22: =L22/D22 -> 0.0012236241 | N22: Theatrical
A23: Puss In Boots FR | B23: Store | C23: 44936 | D23: =SUM('All Email Performance'!E34:E35) -> 17075 | E23: =(D23-F23)/D23 -> 0.99918009 | F23: =SUM('All Email Performance'!G34:G35) -> 14 | G23: =SUM('All Email Performance'!H34:H35) -> 6036 | H23: =G23/D23 -> 0.35349927 | I23: =SUM('All Email Performance'!J34:J35) -> 145 | J23: =I23/D23 -> 0.0084919473 | K23: =I23/G23 -> 0.024022531 | L23: =SUM('All Email Performance'!M34:M35) -> 38 | M23: =L23/D23 -> 0.0022254758 | N23: Store
A24: Puss In Boots EN | B24: Store | C24: 44936 | D24: =SUM('All Email Performance'!E36:E37) -> 322579 | E24: =(D24-F24)/D24 -> 0.99871969 | F24: =SUM('All Email Performance'!G36:G37) -> 413 | G24: =SUM('All Email Performance'!H36:H37) -> 148850 | H24: =G24/D24 -> 0.46143735 | I24: =SUM('All Email Performance'!J36:J37) -> 2098 | J24: =I24/D24 -> 0.0065038332 | K24: =I24/G24 -> 0.014094726 | L24: =SUM('All Email Performance'!M36:M37) -> 543 | M24: =L24/D24 -> 0.0016833086 | N24: Store
A25: Employee Pincode | B25: Other | C25: 44938 | D25: ='All Email Performance'!E38 -> 1672 | E25: =(D25-F25)/D25 -> 1 | F25: ='All Email Performance'!G38 -> 0 | G25: ='All Email Performance'!H38 -> 601 | H25: =G25/D25 -> 0.35944976 | I25: ='All Email Performance'!J38 -> 18 | J25: =I25/D25 -> 0.01076555 | K25: =I25/G25 -> 0.029950083 | L25: ='All Email Performance'!M38 -> 0 | M25: =L25/D25 -> 0 | N25: Other
A26: BTS Yet To Come FR | B26: Theatrical | C26: 44938 | D26: =SUM('All Email Performance'!E39:E40) -> 91091 | E26: =(D26-F26)/D26 -> 0.99880339 | F26: =SUM('All Email Performance'!G39:G40) -> 109 | G26: =SUM('All Email Performance'!H39:H40) -> 25335 | H26: =G26/D26 -> 0.27812846 | I26: =SUM('All Email Performance'!J39:J40) -> 334 | J26: =I26/D26 -> 0.003666663 | K26: =I26/G26 -> 0.013183343 | L26: =SUM('All Email Performance'!M39:M40) -> 192 | M26: =L26/D26 -> 0.0021077823 | N26: Theatrical
A27: BTS Yet To Come EN | B27: Theatrical | C27: 44938 | D27: =SUM('All Email Performance'!E41:E42) -> 1437667 | E27: =(D27-F27)/D27 -> 0.99757246 | F27: =SUM('All Email Performance'!G41:G42) -> 3490 | G27: =SUM('All Email Performance'!H41:H42) -> 513567 | H27: =G27/D27 -> 0.3572225 | I27: =SUM('All Email Performance'!J41:J42) -> 5806 | J27: =I27/D27 -> 0.0040384874 | K27: =I27/G27 -> 0.011305244 | L27: =SUM('All Email Performance'!M41:M42) -> 2879 | M27: =L27/D27 -> 0.00200255 | N27: Theatrical
A28: Friday What's On FR | B28: Theatrical | C28: 44939 | D28: =SUM('All Email Performance'!E43:E44) -> 322909 | E28: =(D28-F28)/D28 -> 0.99769595 | F28: =SUM('All Email Performance'!G43:G44) -> 744 | G28: =SUM('All Email Performance'!H43:H44) -> 112948 | H28: =G28/D28 -> 0.34978276 | I28: =SUM('All Email Performance'!J43:J44) -> 3685 | J28: =I28/D28 -> 0.011411884 | K28: =I28/G28 -> 0.032625633 | L28: =SUM('All Email Performance'!M43:M44) -> 1417 | M28: =L28/D28 -> 0.0043882332 | N28: Theatrical
A29: Friday What's On EN | B29: Theatrical | C29: 44939 | D29: =SUM('All Email Performance'!E45:E46) -> 4292344 | E29: =(D29-F29)/D29 -> 0.9959288 | F29: =SUM('All Email Performance'!G45:G46) -> 17475 | G29: =SUM('All Email Performance'!H45:H46) -> 1562080 | H29: =G29/D29 -> 0.36392237 | I29: =SUM('All Email Performance'!J45:J46) -> 31910 | J29: =I29/D29 -> 0.0074341665 | K29: =I29/G29 -> 0.020427891 | L29: =SUM('All Email Performance'!M45:M46) -> 12369 | M29: =L29/D29 -> 0.0028816423 | N29: Theatrical
A30: Movie Guide EN 24MT | B30: Store | C30: 44939 | D30: ='All Email Performance'!E47 -> 252620 | E30: =(D30-F30)/D30 -> 0.99887974 | F30: ='All Email Performance'!G47 -> 283 | G30: ='All Email Performance'!H47 -> 95330 | H30: =G30/D30 -> 0.37736521 | I30: ='All Email Performance'!J47 -> 2226 | J30: =I30/D30 -> 0.0088116539 | K30: =I30/G30 -> 0.023350467 | L30: ='All Email Performance'!M47 -> 330 | M30: =L30/D30 -> 0.0013063099 | N30: Store
A31: Movie Guide EN | B31: Store | C31: 44939 | D31: ='All Email Performance'!E48 -> 334315 | E31: =(D31-F31)/D31 -> 0.99789121 | F31: ='All Email Performance'!G48 -> 705 | G31: ='All Email Performance'!H48 -> 101194 | H31: =G31/D31 -> 0.30269058 | I31: ='All Email Performance'!J48 -> 2570 | J31: =I31/D31 -> 0.0076873607 | K31: =I31/G31 -> 0.025396763 | L31: ='All Email Performance'!M48 -> 321 | M31: =L31/D31 -> 0.00096017229 | N31: Store
A32: Adv Tickets Ant Man Quantumania FR | B32: Theatrical | C32: 44942 | D32: =SUM('All Email Performance'!E49:E50) -> 345663 | E32: =(D32-F32)/D32 -> 0.99765378 | F32: =SUM('All Email Performance'!G49:G50) -> 811 | G32: =SUM('All Email Performance'!H49:H50) -> 128665 | H32: =G32/D32 -> 0.37222671 | I32: =SUM('All Email Performance'!J49:J50) -> 3462 | J32: =I32/D32 -> 0.010015535 | K32: =I32/G32 -> 0.026907084 | L32: =SUM('All Email Performance'!M49:M50) -> 2181 | M32: =L32/D32 -> 0.0063096137 | N32: Theatrical
A33: Adv Tickets Ant Man Quantumania EN | B33: Theatrical | C33: 44942 | D33: =SUM('All Email Performance'!E51:E52) -> 4461073 | E33: =(D33-F33)/D33 -> 0.9960635 | F33: =SUM('All Email Performance'!G51:G52) -> 17561 | G33: =SUM('All Email Performance'!H51:H52) -> 2115387 | H33: =G33/D33 -> 0.47418794 | I33: =SUM('All Email Performance'!J51:J52) -> 52085 | J33: =I33/D33 -> 0.011675442 | K33: =I33/G33 -> 0.024621972 | L33: =SUM('All Email Performance'!M51:M52) -> 22135 | M33: =L33/D33 -> 0.0049618108 | N33: Theatrical
A34: Tuesday Deals FR | B34: Theatrical | C34: 44943 | D34: =SUM('All Email Performance'!E53:E54) -> 47864 | E34: =(D34-F34)/D34 -> 0.9988718 | F34: =SUM('All Email Performance'!G53:G54) -> 54 | G34: =SUM('All Email Performance'!H53:H54) -> 17790 | H34: =G34/D34 -> 0.37167809 | I34: =SUM('All Email Performance'!J53:J54) -> 554 | J34: =I34/D34 -> 0.011574461 | K34: =I34/G34 -> 0.031141091 | L34: =SUM('All Email Performance'!M53:M54) -> 133 | M34: =L34/D34 -> 0.0027787063 | N34: Theatrical
A35: Tuesday Deals EN | B35: Theatrical | C35: 44943 | D35: =SUM('All Email Performance'!E55:E56) -> 626657 | E35: =(D35-F35)/D35 -> 0.99802125 | F35: =SUM('All Email Performance'!G55:G56) -> 1240 | G35: =SUM('All Email Performance'!H55:H56) -> 245646 | H35: =G35/D35 -> 0.39199434 | I35: =SUM('All Email Performance'!J55:J56) -> 5174 | J35: =I35/D35 -> 0.0082565103 | K35: =I35/G35 -> 0.02106283 | L35: =SUM('All Email Performance'!M55:M56) -> 1280 | M35: =L35/D35 -> 0.0020425847 | N35: Theatrical
A36: Pathaan Challenger EN | B36: Theatrical | C36: 44944 | D36: =SUM('All Email Performance'!E57:E58) -> 12610 | E36: =(D36-F36)/D36 -> 0.99706582 | F36: =SUM('All Email Performance'!G57:G58) -> 37 | G36: =SUM('All Email Performance'!H57:H58) -> 5690 | H36: =G36/D36 -> 0.45122918 | I36: =SUM('All Email Performance'!J57:J58) -> 87 | J36: =I36/D36 -> 0.0068992863 | K36: =I36/G36 -> 0.015289982 | L36: =SUM('All Email Performance'!M57:M58) -> 31 | M36: =L36/D36 -> 0.0024583664 | N36: Theatrical
A37: Pathaan Primary Audience EN | B37: Theatrical | C37: 44944 | D37: =SUM('All Email Performance'!E59:E60) -> 471641 | E37: =(D37-F37)/D37 -> 0.99774829 | F37: =SUM('All Email Performance'!G59:G60) -> 1062 | G37: =SUM('All Email Performance'!H59:H60) -> 252112 | H37: =G37/D37 -> 0.53454216 | I37: =SUM('All Email Performance'!J59:J60) -> 7258 | J37: =I37/D37 -> 0.015388823 | K37: =I37/G37 -> 0.028788792 | L37: =SUM('All Email Performance'!M59:M60) -> 742 | M37: =L37/D37 -> 0.0015732305 | N37: Theatrical
A38: Cast Pass | B38: Other | C38: 44944 | D38: ='All Email Performance'!E61 -> 315 | E38: =(D38-F38)/D38 -> 1 | F38: ='All Email Performance'!G61 -> 0 | G38: ='All Email Performance'!H61 -> 82 | H38: =G38/D38 -> 0.26031746 | I38: ='All Email Performance'!J61 -> 7 | J38: =I38/D38 -> 0.022222222 | K38: =I38/G38 -> 0.085365854 | L38: ='All Email Performance'!M61 -> 0 | M38: =L38/D38 -> 0 | N38: Other
A39: National Popcorn Day FR | B39: Theatrical | C39: 44944 | D39: ='All Email Performance'!E62 -> 111097 | E39: =(D39-F39)/D39 -> 0.99912689 | F39: ='All Email Performance'!G62 -> 97 | G39: ='All Email Performance'!H62 -> 39756 | H39: =G39/D39 -> 0.35784945 | I39: ='All Email Performance'!J62 -> 1074 | J39: =I39/D39 -> 0.0096672277 | K39: =I39/G39 -> 0.02701479 | L39: ='All Email Performance'!M62 -> 54 | M39: =L39/D39 -> 0.00048606173 | N39: Theatrical
A40: National Popcorn Day EN | B40: Theatrical | C40: 44944 | D40: ='All Email Performance'!E63 -> 1896017 | E40: =(D40-F40)/D40 -> 0.997115 | F40: ='All Email Performance'!G63 -> 5470 | G40: ='All Email Performance'!H63 -> 860136 | H40: =G40/D40 -> 0.45365416 | I40: ='All Email Performance'!J63 -> 19533 | J40: =I40/D40 -> 0.010302123 | K40: =I40/G40 -> 0.022709199 | L40: ='All Email Performance'!M63 -> 2275 | M40: =L40/D40 -> 0.0011998838 | N40: Theatrical
A41: National Popcorn Day FR | B41: Store | C41: 44944 | D41: =SUM('All Email Performance'!E64:E65) -> 25874 | E41: =(D41-F41)/D41 -> 0.99907243 | F41: =SUM('All Email Performance'!G64:G65) -> 24 | G41: =SUM('All Email Performance'!H64:H65) -> 9264 | H41: =G41/D41 -> 0.35804282 | I41: =SUM('All Email Performance'!J64:J65) -> 224 | J41: =I41/D41 -> 0.0086573394 | K41: =I41/G41 -> 0.02417962 | L41: =SUM('All Email Performance'!M64:M65) -> 63 | M41: =L41/D41 -> 0.0024348767 | N41: Store
...

Sheet Weekly View
A1: Week | C1: Sends | D1: Unique Opens | E1: Open Rate | F1: Clicks | G1: CTR | H1: CTOR | I1: Unsubscribes | J1: % of Clicks that are Unsubscribes | K1: Unsubscribe Rate
A2: Week 1 | B2: January 2 - January 8, 2023 | C2: 5901273 | D2: 2179320 | E2: =D2/C2 -> 0.36929659 | F2: 57769 | G2: =F2/C2 -> 0.0097892438 | H2: =F2/D2 -> 0.02650781 | I2: 18747 | J2: =I2/F2 -> 0.32451661 | K2: =I2/C2 -> 0.0031767722
A3: Week 2 | B3: January 9 - January 15, 2023 | C3: 10498117 | D3: 3891651 | E3: =D3/C3 -> 0.37069991 | F3: 69398 | G3: =F3/C3 -> 0.0066105188 | H3: =F3/D3 -> 0.017832534 | I3: 25931 | J3: =I3/F3 -> 0.3736563 | K3: =I3/C3 -> 0.002470062
A4: Week 3 | B4: January 16 - January 22, 2023 | C4: 14749691 | D4: 6393713 | E4: =D4/C4 -> 0.43348115 | F4: 142811 | G4: =F4/C4 -> 0.0096823045 | H4: =F4/D4 -> 0.022336161 | I4: 41254 | J4: =I4/F4 -> 0.28887131 | K4: =I4/C4 -> 0.0027969399
A5: Week 4 | B5: January 23 - January 29, 2023 | C5: 11960843 | D5: 4691733 | E5: =D5/C5 -> 0.39225772 | F5: 87659 | G5: =F5/C5 -> 0.0073288313 | H5: =F5/D5 -> 0.018683715 | I5: 31449 | J5: =I5/F5 -> 0.35876522 | K5: =I5/C5 -> 0.0026293297
A6: Week 5 | B6: January 30 - February 5, 2023 | C6: 11983400 | D6: 4480708 | E6: =D6/C6 -> 0.37390957 | F6: 125360 | G6: =F6/C6 -> 0.010461138 | H6: =F6/D6 -> 0.027977721 | I6: 28045 | J6: =I6/F6 -> 0.2237157 | K6: =I6/C6 -> 0.0023403208
A7: Week 6 | B7: February 6 - February 12, 2023 | C7: 16809857 | D7: 6439077 | E7: =D7/C7 -> 0.38305365 | F7: 95106 | G7: =F7/C7 -> 0.0056577519 | H7: =F7/D7 -> 0.014770129 | I7: 42128 | J7: =I7/F7 -> 0.44295838 | K7: =I7/C7 -> 0.0025061486
A8: Week 7 | B8: February 13 - February 19, 2023 | C8: 11817737 | D8: 4372026 | E8: =D8/C8 -> 0.36995459 | F8: 76230 | G8: =F8/C8 -> 0.0064504736 | H8: =F8/D8 -> 0.017435852 | I8: 23746 | J8: =I8/F8 -> 0.31150466 | K8: =I8/C8 -> 0.0020093526
A9: Week 8 | B9: February 20 - February 26, 2023 | C9: 18019341 | D9: 6916675 | E9: =D9/C9 -> 0.38384728 | F9: 151558 | G9: =F9/C9 -> 0.0084108514 | H9: =F9/D9 -> 0.021911974 | I9: 38055 | J9: =I9/F9 -> 0.25109199 | K9: =I9/C9 -> 0.0021118974
A10: Week 9 | B10: February 27 - March 5, 2023 | C10: 13206205 | D10: 5032492 | E10: =D10/C10 -> 0.38107026 | F10: 81232 | G10: =F10/C10 -> 0.0061510479 | H10: =F10/D10 -> 0.016141506 | I10: 28490 | J10: =I10/F10 -> 0.35072385 | K10: =I10/C10 -> 0.0021573192
A11: Week 10 | B11: March 6 - March 12, 2023 | C11: 13300772 | D11: 4941364 | E11: =D11/C11 -> 0.37150956 | F11: 78522 | G11: =F11/C11 -> 0.0059035671 | H11: =F11/D11 -> 0.015890754 | I11: 17970 | J11: =I11/F11 -> 0.22885306 | K11: =I11/C11 -> 0.0013510494
A12: Week 11 | B12: March 13 - March 19, 2023 | C12: 16557064 | D12: 6645473 | E12: =D12/C12 -> 0.40136784 | F12: 99161 | G12: =F12/C12 -> 0.0059890449 | H12: =F12/D12 -> 0.014921586 | I12: 16674 | J12: =I12/F12 -> 0.16815079 | K12: =I12/C12 -> 0.0010070626
A13: Week 12 | B13: March 20 - March 26, 2023 | C13: 5888053 | D13: 2168000 | E13: =D13/C13 -> 0.36820321 | F13: 40434 | G13: =F13/C13 -> 0.0068671257 | H13: =F13/D13 -> 0.018650369 | I13: 8996 | J13: =I13/F13 -> 0.22248603 | K13: =I13/C13 -> 0.0015278395
... A26: Week 25 | B26: June 19 - June 25, 2023 | C26: 12813458 | D26: 4404446 | E26: =D26/C26 -> 0.34373594 | F26: 60973 | G26: =F26/C26 -> 0.0047585125 | H26: =F26/D26 -> 0.013843512 | I26: 14742 | J26: =I26/F26 -> 0.24177915 | K26: =I26/C26 -> 0.0011505091
A27: Grand Total (YTD) | C27: =SUM(C2:C26) -> 323128325 | D27: =SUM(D2:D26) -> 120178596 | E27: =D27/C27 -> 0.3719222 | F27: =SUM(F2:F26) -> 1989848 | G27: =F27/C27 -> 0.0061580736 | H27: =F27/D27 -> 0.016557424 | I27: =SUM(I2:I26) -> 540782 | J27: =I27/F27 -> 0.27177051 | K27: =I27/C27 -> 0.0016735828
A30: Campaign Monitor 2021 Industry Benchmarks (Media, Entertainment, Publishing) | E30: 0.239 | G30: 0.029 | H30: 0.124 | K30: 0.001

Sheet Friday What's On
A1: Email Name | B1: Audience | C1: Business Unit | D1: Send Date | E1: Sends | F1: Delivery Rate | G1: Overall Bounces | H1: Unique Opens | I1: Open Rate | J1: Unique Clicks | K1: CTR | L1: CTO | M1: Unsubscribes | N1: Unsubscribe Rate | O1: Reporting
A2: Friday What's On FR | B2: SCENE | C2: Theatrical | D2: 44932 | E2: 95994 | F2: =(E2-G2)/E2 -> 0.99888535 | G2: 107 | H2: 30775 | I2: =H2/E2 -> 0.32059295 | J2: 946 | K2: =J2/E2 -> 0.0098547826 | L2: =J2/H2 -> 0.030739236 | M2: 86 | N2: =M2/E2 -> 0.00089588933 | O2: Theatrical
A3: Friday What's On EN | B3: SCENE | C3: Theatrical | D3: 44932 | E3: 1750473 | F3: =(E3-G3)/E3 -> 0.99671403 | G3: 5752 | H3: 625509 | I3: =H3/E3 -> 0.35733713 | J3: 12915 | K3: =J3/E3 -> 0.0073780058 | L3: =J3/H3 -> 0.020647185 | M3: 2797 | N3: =M3/E3 -> 0.0015978538 | O3: Theatrical
A4: Friday What's On FR | B4: CONNECT | C4: Theatrical | D4: 44932 | E4: 223652 | F4: =(E4-G4)/E4 -> 0.99710711 | G4: 647 | H4: 78135 | I4: =H4/E4 -> 0.34935972 | J4: 3430 | K4: =J4/E4 -> 0.015336326 | L4: =J4/H4 -> 0.043898381 | M4: 1896 | N4: =M4/E4 -> 0.008477456 | O4: Theatrical
A5: Friday What's On EN | B5: CONNECT | C5: Theatrical | D5: 44932 | E5: 2511131 | F5: =(E5-G5)/E5 -> 0.99525075 | G5: 11926 | H5: 923449 | I5: =H5/E5 -> 0.36774226 | J5: 23859 | K5: =J5/E5 -> 0.0095012964 | L5: =J5/H5 -> 0.025836836 | M5: 11684 | N5: =M5/E5 -> 0.0046528835 | O5: Theatrical
A6: Friday What's On FR | B6: SCENE | C6: Theatrical | D6: 44939 | E6: 96595 | F6: =(E6-G6)/E6 -> 0.99883017 | G6: 113 | H6: 31810 | I6: =H6/E6 -> 0.32931311 | J6: 847 | K6: =J6/E6 -> 0.0087685698 | L6: =J6/H6 -> 0.026626847 | M6: 78 | N6: =M6/E6 -> 0.00080749521 | O6: Theatrical
A7: Friday What's On FR | B7: CONNECT | C7: Theatrical | D7: 44939 | E7: 226314 | F7: =(E7-G7)/E7 -> 0.99721184 | G7: 631 | H7: 81138 | I7: =H7/E7 -> 0.35851958 | J7: 2838 | K7: =J7/E7 -> 0.012540099 | L7: =J7/H7 -> 0.034977446 | M7: 1339 | N7: =M7/E7 -> 0.0059165584 | O7: Theatrical
A8: Friday What's On EN | B8: SCENE | C8: Theatrical | D8: 44939 | E8: 1768850 | F8: =(E8-G8)/E8 -> 0.99685219 | G8: 5568 | H8: 643388 | I8: =H8/E8 -> 0.36373237 | J8: 11627 | K8: =J8/E8 -> 0.0065731973 | L8: =J8/H8 -> 0.018071521 | M8: 2397 | N8: =M8/E8 -> 0.0013551177 | O8: Theatrical
A9: Friday What's On EN | B9: CONNECT | C9: Theatrical | D9: 44939 | E9: 2523494 | F9: =(E9-G9)/E9 -> 0.99528154 | G9: 11907 | H9: 918692 | I9: =H9/E9 -> 0.36405555 | J9: 20283 | K9: =J9/E9 -> 0.0080376652 | L9: =J9/H9 -> 0.022078128 | M9: 9972 | N9: =M9/E9 -> 0.0039516638 | O9: Theatrical
A10: Friday What's On FR | B10: CONNECT | C10: Theatrical | D10: 44946 | E10: 198628 | F10: =(E10-G10)/E10 -> 0.99706486 | G10: 583 | H10: 68163 | I10: =H10/E10 -> 0.34316914 | J10: 2069 | K10: =J10/E10 -> 0.010416457 | L10: =J10/H10 -> 0.030353711 | M10: 989 | N10: =M10/E10 -> 0.004979157 | O10: Theatrical
A11: Friday What's On FR | B11: SCENE | C11: Theatrical | D11: 44946 | E11: 96804 | F11: =(E11-G11)/E11 -> 0.99904963 | G11: 92 | H11: 31041 | I11: =H11/E11 -> 0.32065824 | J11: 747 | K11: =J11/E11 -> 0.0077166233 | L11: =J11/H11 -> 0.024064946 | M11: 60 | N11: =M11/E11 -> 0.0006198091 | O11: Theatrical
A12: Friday What's On EN | B12: SCENE | C12: Theatrical | D12: 44946 | E12: 1657825 | F12: =(E12-G12)/E12 -> 0.99766501 | G12: 3871 | H12: 754373 | I12: =H12/E12 -> 0.45503778 | J12: 13840 | K12: =J12/E12 -> 0.0083482877 | L12: =J12/H12 -> 0.018346362 | M12: 2343 | N12: =M12/E12 -> 0.0014132975 | O12: Theatrical
A13: Friday What's On EN | B13: CONNECT | C13: Theatrical | D13: 44946 | E13: 2181188 | F13: =(E13-G13)/E13 -> 0.9952833 | G13: 10288 | H13: 789271 | I13: =H13/E13 -> 0.36185372 | J13: 15872 | K13: =J13/E13 -> 0.0072767684 | L13: =J13/H13 -> 0.020109696 | M13: 6565 | N13: =M13/E13 -> 0.0030098277 | O13: Theatrical
... A101: Friday What's On EN | B101: CONNECT | C101: Theatrical | D101: 45100 | E101: 2348491 | F101: =(E101-G101)/E101 -> 0.99773003 | G101: 5331 | H101: 752290 | I101: =H101/E101 -> 0.3203291 | J101: 9193 | K101: =J101/E101 -> 0.0039144285 | L101: =J101/H101 -> 0.012220022 | M101: 3179 | N101: =M101/E101 -> 0.0013536352 | O101: Theatrical
A103: All 2023 Friday What's On Data | E103: =SUM(E2:E101) -> 110393094 | F103: =(E103-G103)/E103 -> 0.99682139 | G103: =SUM(G2:G101) -> 350897 | H103: =SUM(H2:H101) -> 38342700 | I103: =H103/E103 -> 0.34732879 | J103: =SUM(J2:J101) -> 606555 | K103: =J103/E103 -> 0.0054945013 | L103: =J103/H103 -> 0.015819308 | M103: =SUM(M2:M101) -> 182222 | N103: =M103/E103 -> 0.0016506649
M104: =M103/J103 -> 0.30042123
A106: Campaign Monitor 2021 Industry Benchmarks (Media, Entertainment, Publishing) | I106: 0.239 | K106: 0.029 | L106: 0.124 | N106: 0.001

Sheet Tuesday Deals
A1: Email Name | B1: Audience | C1: Business Unit | D1: Send Date | E1: Sends | F1: Delivery Rate | G1: Overall Bounces | H1: Unique Opens | I1: Open Rate | J1: Unique Clicks | K1: CTR | L1: CTO | M1: Unsubscribes | N1: Unsubscribe Rate | O1: Reporting
A2: Tuesday Deals FR | B2: SCENE | C2: Theatrical | D2: 44929 | E2: 22244 | F2: =(E2-G2)/E2 -> 0.99878619 | G2: 27 | H2: 7887 | I2: =H2/E2 -> 0.35456752 | J2: 378 | K2: =J2/E2 -> 0.016993347 | L2: =J2/H2 -> 0.047926968 | M2: 19 | N2: =M2/E2 -> 0.00085416292 | O2: Theatrical
A3: Tuesday Deals EN | B3: SCENE | C3: Theatrical | D3: 44929 | E3: 194636 | F3: =(E3-G3)/E3 -> 0.99814526 | G3: 361 | H3: 69766 | I3: =H3/E3 -> 0.35844345 | J3: 1647 | K3: =J3/E3 -> 0.0084619495 | L3: =J3/H3 -> 0.023607488 | M3: 157 | N3: =M3/E3 -> 0.00080663392 | O3: Theatrical
A4: Tuesday Deals FR | B4: CONNECT | C4: Theatrical | D4: 44929 | E4: 17887 | F4: =(E4-G4)/E4 -> 0.99921731 | G4: 14 | H4: 6856 | I4: =H4/E4 -> 0.38329513 | J4: 224 | K4: =J4/E4 -> 0.012523061 | L4: =J4/H4 -> 0.032672112 | M4: 38 | N4: =M4/E4 -> 0.0021244479 | O4: Theatrical
A5: Tuesday Deals EN | B5: CONNECT | C5: Theatrical | D5: 44929 | E5: 354949 | F5: =(E5-G5)/E5 -> 0.99838287 | G5: 574 | H5: 141863 | I5: =H5/E5 -> 0.3996715 | J5: 2270 | K5: =J5/E5 -> 0.006395285 | L5: =J5/H5 -> 0.016001353 | M5: 606 | N5: =M5/E5 -> 0.0017072875 | O5: Theatrical
A6: Tuesday Deals FR | B6: CONNECT | C6: Theatrical | D6: 44936 | E6: 18438 | F6: =(E6-G6)/E6 -> 0.99940341 | G6: 11 | H6: 7217 | I6: =H6/E6 -> 0.39141989 | J6: 237 | K6: =J6/E6 -> 0.012853889 | L6: =J6/H6 -> 0.03283913 | M6: 34 | N6: =M6/E6 -> 0.0018440178 | O6: Theatrical
A7: Tuesday Deals FR | B7: SCENE | C7: Theatrical | D7: 44936 | E7: 22406 | F7: =(E7-G7)/E7 -> 0.99928591 | G7: 16 | H7: 8105 | I7: =H7/E7 -> 0.36173346 | J7: 343 | K7: =J7/E7 -> 0.0153084 | L7: =J7/H7 -> 0.042319556 | M7: 13 | N7: =M7/E7 -> 0.00058020173 | O7: Theatrical
A8: Tuesday Deals EN | B8: SCENE | C8: Theatrical | D8: 44936 | E8: 196490 | F8: =(E8-G8)/E8 -> 0.99831544 | G8: 331 | H8: 71868 | I8: =H8/E8 -> 0.36575907 | J8: 1795 | K8: =J8/E8 -> 0.009135325 | L8: =J8/H8 -> 0.024976346 | M8: 123 | N8: =M8/E8 -> 0.00062598606 | O8: Theatrical
A9: Tuesday Deals EN | B9: CONNECT | C9: Theatrical | D9: 44936 | E9: 358419 | F9: =(E9-G9)/E9 -> 0.99861056 | G9: 498 | H9: 141898 | I9: =H9/E9 -> 0.39589977 | J9: 2425 | K9: =J9/E9 -> 0.0067658244 | L9: =J9/H9 -> 0.017089741 | M9: 556 | N9: =M9/E9 -> 0.001551257 | O9: Theatrical
A10: Tuesday Deals FR | B10: SCENE | C10: Theatrical | D10: 44943 | E10: 22648 | F10: =(E10-G10)/E10 -> 0.99920523 | G10: 18 | H10: 8068 | I10: =H10/E10 -> 0.35623455 | J10: 265 | K10: =J10/E10 -> 0.011700812 | L10: =J10/H10 -> 0.032845811 | M10: 17 | N10: =M10/E10 -> 0.00075061816 | O10: Theatrical
A11: Tuesday Deals FR | B11: CONNECT | C11: Theatrical | D11: 44943 | E11: 25216 | F11: =(E11-G11)/E11 -> 0.99857234 | G11: 36 | H11: 9722 | I11: =H11/E11 -> 0.38554886 | J11: 289 | K11: =J11/E11 -> 0.011460977 | L11: =J11/H11 -> 0.029726394 | M11: 116 | N11: =M11/E11 -> 0.0046002538 | O11: Theatrical
A12: Tuesday Deals EN | B12: SCENE | C12: Theatrical | D12: 44943 | E12: 207913 | F12: =(E12-G12)/E12 -> 0.99800878 | G12: 414 | H12: 77636 | I12: =H12/E12 -> 0.37340618 | J12: 1924 | K12: =J12/E12 -> 0.0092538706 | L12: =J12/H12 -> 0.024782317 | M12: 141 | N12: =M12/E12 -> 0.00067816827 | O12: Theatrical
A13: Tuesday Deals EN | B13: CONNECT | C13: Theatrical | D13: 44943 | E13: 418744 | F13: =(E13-G13)/E13 -> 0.99802743 | G13: 826 | H13: 168010 | I13: =H13/E13 -> 0.40122366 | J13: 3250 | K13: =J13/E13 -> 0.0077613052 | L13: =J13/H13 -> 0.019344087 | M13: 1139 | N13: =M13/E13 -> 0.002720039 | O13: Theatrical
... A103: Tuesday Deals EN | B103: CONNECT | C103: Theatrical | D103: 45097 | E103: 477617 | F103: =(E103-G103)/E103 -> 0.99774296 | G103: 1078 | H103: 177179 | I103: =H103/E103 -> 0.3709646 | J103: 2060 | K103: =J103/E103 -> 0.0043130793 | L103: =J103/H103 -> 0.01162666 | M103: 406 | N103: =M103/E103 -> 0.00085005349 | O103: Theatrical
A105: All 2023 Tuesday Deals Data | E105: =SUM(E2:E103) -> 17955970 | F105: =(E105-G105)/E105 -> 0.99730597 | G105: =SUM(G2:G103) -> 48374 | H105: =SUM(H2:H103) -> 6898864 | I105: =H105/E105 -> 0.38421004 | J105: =SUM(J2:J103) -> 120284 | K105: =J105/E105 -> 0.0066988305 | L105: =J105/H105 -> 0.017435334 | M105: =SUM(M2:M103) -> 17225 | N105: =M105/E105 -> 0.00095929098
M106: =M105/J105 -> 0.14320275
A108: Campaign Monitor 2021 Industry Benchmarks (Media, Entertainment, Publishing) | I108: 0.239 | K108: 0.029 | L108: 0.124 | N108: 0.001

Sheet Store Newsletter
A1: Email Name | B1: Audience | C1: Business Unit | D1: Send Date | E1: Sends | F1: Delivery Rate | G1: Overall Bounces | H1: Unique Opens | I1: Open Rate | J1: Unique Clicks | K1: CTR | L1: CTO | M1: Unsubscribes | N1: Unsubscribe Rate | O1: Reporting
A2: Movie Guide EN 24MT | B2: CONNECT | C2: Store | D2: 44932 | E2: 229503 | F2: =(E2-G2)/E2 -> 0.99866233 | G2: 307 | H2: 105460 | I2: =H2/E2 -> 0.45951469 | J2: 2616 | K2: =J2/E2 -> 0.011398544 | L2: =J2/H2 -> 0.024805614 | M2: 317 | N2: =M2/E2 -> 0.0013812456 | O2: Store
A3: Movie Guide EN | B3: CONNECT | C3: Store | D3: 44932 | E3: 327320 | F3: =(E3-G3)/E3 -> 0.9971618 | G3: 929 | H3: 123722 | I3: =H3/E3 -> 0.37798485 | J3: 3484 | K3: =J3/E3 -> 0.010644018 | L3: =J3/H3 -> 0.028159907 | M3: 473 | N3: =M3/E3 -> 0.001445069 | O3: Store
A4: Movie Guide FR | B4: CONNECT | C4: Store | D4: 44933 | E4: 13458 | F4: =(E4-G4)/E4 -> 0.99903403 | G4: 13 | H4: 4436 | I4: =H4/E4 -> 0.32961807 | J4: 200 | K4: =J4/E4 -> 0.014861049 | L4: =J4/H4 -> 0.045085663 | M4: 42 | N4: =M4/E4 -> 0.0031208203 | O4: Store
A5: Movie Guide EN 24MT | B5: CONNECT | C5: Store | D5: 44939 | E5: 252620 | F5: =(E5-G5)/E5 -> 0.99887974 | G5: 283 | H5: 95330 | I5: =H5/E5 -> 0.37736521 | J5: 2226 | K5: =J5/E5 -> 0.0088116539 | L5: =J5/H5 -> 0.023350467 | M5: 330 | N5: =M5/E5 -> 0.0013063099 | O5: Store
A6: Movie Guide EN | B6: CONNECT | C6: Store | D6: 44939 | E6: 334315 | F6: =(E6-G6)/E6 -> 0.99789121 | G6: 705 | H6: 101194 | I6: =H6/E6 -> 0.30269058 | J6: 2570 | K6: =J6/E6 -> 0.0076873607 | L6: =J6/H6 -> 0.025396763 | M6: 321 | N6: =M6/E6 -> 0.00096017229 | O6: Store
A7: Movie Guide EN 24MT | B7: CONNECT | C7: Store | D7: 44946 | E7: 251190 | F7: =(E7-G7)/E7 -> 0.99849914 | G7: 377 | H7: 116570 | I7: =H7/E7 -> 0.46407102 | J7: 2464 | K7: =J7/E7 -> 0.0098093077 | L7: =J7/H7 -> 0.021137514 | M7: 385 | N7: =M7/E7 -> 0.0015327043 | O7: Store
A8: Movie Guide EN | B8: CONNECT | C8: Store | D8: 44946 | E8: 334231 | F8: =(E8-G8)/E8 -> 0.9970679 | G8: 980 | H8: 127214 | I8: =H8/E8 -> 0.380617 | J8: 3076 | K8: =J8/E8 -> 0.0092032157 | L8: =J8/H8 -> 0.024179729 | M8: 473 | N8: =M8/E8 -> 0.0014151889 | O8: Store
A9: Movie Guide FR | B9: CONNECT | C9: Store | D9: 44947 | E9: 15444 | F9: =(E9-G9)/E9 -> 0.9990935 | G9: 14 | H9: 5022 | I9: =H9/E9 -> 0.32517483 | J9: 173 | K9: =J9/E9 -> 0.011201761 | L9: =J9/H9 -> 0.034448427 | M9: 17 | N9: =M9/E9 -> 0.0011007511 | O9: Store
A10: Movie Guide EN | B10: CONNECT | C10: Store | D10: 44953 | E10: 334048 | F10: =(E10-G10)/E10 -> 0.99770093 | G10: 768 | H10: 122888 | I10: =H10/E10 -> 0.36787528 | J10: 3571 | K10: =J10/E10 -> 0.01069008 | L10: =J10/H10 -> 0.029058981 | M10: 581 | N10: =M10/E10 -> 0.001739271 | O10: Store
A11: Movie Guide EN 24MT | B11: CONNECT | C11: Store | D11: 44953 | E11: 250619 | F11: =(E11-G11)/E11 -> 0.99901444 | G11: 247 | H11: 114442 | I11: =H11/E11 -> 0.45663737 | J11: 3246 | K11: =J11/E11 -> 0.012951931 | L11: =J11/H11 -> 0.028363713 | M11: 438 | N11: =M11/E11 -> 0.0017476728 | O11: Store
A12: Movie Guide EN 24MT | B12: CONNECT | C12: Store | D12: 44960 | E12: 249719 | F12: =(E12-G12)/E12 -> 0.99873458 | G12: 316 | H12: 113555 | I12: =H12/E12 -> 0.45473112 | J12: 1651 | K12: =J12/E12 -> 0.0066114312 | L12: =J12/H12 -> 0.01453921 | M12: 348 | N12: =M12/E12 -> 0.0013935664 | O12: Store
A13: Movie Guide EN | B13: CONNECT | C13: Store | D13: 44960 | E13: 333398 | F13: =(E13-G13)/E13 -> 0.99789141 | G13: 703 | H13: 124313 | I13: =H13/E13 -> 0.37286666 | J13: 2170 | K13: =J13/E13 -> 0.0065087373 | L13: =J13/H13 -> 0.017455938 | M13: 394 | N13: =M13/E13 -> 0.0011817707 | O13: Store
... A64: Movie Guide FR | B64: CONNECT | C64: Store | D64: 45101 | E64: 14954 | F64: =(E64-G64)/E64 -> 0.99819446 | G64: 27 | H64: 4698 | I64: =H64/E64 -> 0.31416343 | J64: 191 | K64: =J64/E64 -> 0.012772502 | L64: =J64/H64 -> 0.040655598 | M64: 16 | N64: =M64/E64 -> 0.0010699478 | O64: Store
A66: All 2023 Store Newsletter Data | E66: =SUM(E2:E64) -> 14520938 | F66: =(E66-G66)/E66 -> 0.99698367 | G66: =SUM(G2:G64) -> 43800 | H66: =SUM(H2:H64) -> 5753444 | I66: =H66/E66 -> 0.3962171 | J66: =SUM(J2:J64) -> 126121 | K66: =J66/E66 -> 0.0086854582 | L66: =J66/H66 -> 0.021920957 | M66: =SUM(M2:M64) -> 14795 | N66: =M66/E66 -> 0.0010188736
M67: =M66/J66 -> 0.11730798
A69: Movie Guide EN 24 MT | E69: =E2+E5+E7+E11+E12+E16+E17+E20+E22+E25+E27+E30+E32+E35+E37+E41+E42+E45+E47+E50+E52+E55+E57+E60+E62 -> 6011042 | F69: =(E69-G69)/E69 -> 0.99777626 | G69: =G2+G5+G7+G11+G12+G16+G17+G20+G22+G25+G27+G30+G32+G35+G37+G41+G42+G45+G47+G50+G52+G55+G57+G60+G62 -> 13367 | H69: =H2+H5+H7+H11+H12+H16+H17+H20+H22+H25+H27+H30+H32+H35+H37+H41+H42+H45+H47+H50+H52+H55+H57+H60+H62 -> 2679910 | I69: =H69/E69 -> 0.44583119 | J69: =J2+J5+J7+J11+J12+J16+J17+J20+J22+J25+J27+J30+J32+J35+J37+J41+J42+J45+J47+J50+J52+J55+J57+J60+J62 -> 55666 | K69: =J69/E69 -> 0.009260624 | L69: =J69/H69 -> 0.020771593 | M69: =M2+M5+M7+M11+M12+M16+M17+M20+M22+M25+M27+M30+M32+M35+M37+M41+M42+M45+M47+M50+M52+M55+M57+M60+M62 -> 6298 | N69: =M69/E69 -> 0.0010477385
M70: =M69/J69 -> 0.11313908
A72: Movie Guide EN | E72: =E3+E6+E8+E10+E13+E15+E18+E21+E23+E26+E28+E31+E33+E36+E38+E40+E43+E46+E48+E51+E53+E56+E58+E61+E63 -> 8316358 | F72: =(E72-G72)/E72 -> 0.99640095 | G72: =G3+G6+G8+G10+G13+G15+G18+G21+G23+G26+G28+G31+G33+G36+G38+G40+G43+G46+G48+G51+G53+G56+G58+G61+G63 -> 29931 | H72: =H3+H6+H8+H10+H13+H15+H18+H21+H23+H26+H28+H31+H33+H36+H38+H40+H43+H46+H48+H51+H53+H56+H58+H61+H63 -> 3011257 | I72: =H72/E72 -> 0.36208843 | J72: =J3+J6+J8+J10+J13+J15+J18+J21+J23+J26+J28+J31+J33+J36+J38+J40+J43+J46+J48+J51+J53+J56+J58+J61+J63 -> 67871 | K72: =J72/E72 -> 0.0081611446 | L72: =J72/H72 -> 0.022539092 | M72: =M3+M6+M8+M10+M13+M15+M18+M21+M23+M26+M28+M31+M33+M36+M38+M40+M43+M46+M48+M51+M53+M56+M58+M61+M63 -> 8238 | N72: =M72/E72 -> 0.00099057785
M73: =M72/J72 -> 0.12137732
A75: Movie Guide FR | E75: =E9+E4+E14+E19+E24+E29+E34+E39+E44+E49+E54+E59+E64 -> 193538 | F75: =(E75-G75)/E75 -> 0.99740619 | G75: =G9+G4+G14+G19+G24+G29+G34+G39+G44+G49+G54+G59+G64 -> 502 | H75: =H9+H4+H14+H19+H24+H29+H34+H39+H44+H49+H54+H59+H64 -> 62277 | I75: =H75/E75 -> 0.32178177 | J75: =J9+J4+J14+J19+J24+J29+J34+J39+J44+J49+J54+J59+J64 -> 2584 | K75: =J75/E75 -> 0.013351383 | L75: =J75/H75 -> 0.041492044 | M75: =M9+M4+M14+M19+M24+M29+M34+M39+M44+M49+M54+M59+M64 -> 259 | N75: =M75/E75 -> 0.0013382385
M76: =M75/J75 -> 0.1002322
A78: Campaign Monitor 2021 Industry Benchmarks (Media, Entertainment, Publishing) | I78: 0.239 | K78: 0.029 | L78: 0.124 | N78: 0.001

Sheet Theatrical
A1: Email Name | B1: Audience | C1: Business Unit | D1: Send Date | E1: Sends | F1: Delivery Rate | G1: Overall Bounces | H1: Unique Opens | I1: Open Rate | J1: Unique Clicks | K1: CTR | L1: CTO | M1: Unsubscribes | N1: Unsubscribe Rate | O1: Reporting
A2: Tuesday Deals FR | B2: SCENE | C2: Theatrical | D2: 44929 | E2: 22244 | F2: =(E2-G2)/E2 -> 0.99878619 | G2: 27 | H2: 7887 | I2: =H2/E2 -> 0.35456752 | J2: 378 | K2: =J2/E2 -> 0.016993347 | L2: =J2/H2 -> 0.047926968 | M2: 19 | N2: =M2/E2 -> 0.00085416292 | O2: Theatrical
A3: Tuesday Deals EN | B3: SCENE | C3: Theatrical | D3: 44929 | E3: 194636 | F3: =(E3-G3)/E3 -> 0.99814526 | G3: 361 | H3: 69766 | I3: =H3/E3 -> 0.35844345 | J3: 1647 | K3: =J3/E3 -> 0.0084619495 | L3: =J3/H3 -> 0.023607488 | M3: 157 | N3: =M3/E3 -> 0.00080663392 | O3: Theatrical
A4: Tuesday Deals FR | B4: CONNECT | C4: Theatrical | D4: 44929 | E4: 17887 | F4: =(E4-G4)/E4 -> 0.99921731 | G4: 14 | H4: 6856 | I4: =H4/E4 -> 0.38329513 | J4: 224 | K4: =J4/E4 -> 0.012523061 | L4: =J4/H4 -> 0.032672112 | M4: 38 | N4: =M4/E4 -> 0.0021244479 | O4: Theatrical
A5: Tuesday Deals EN | B5: CONNECT | C5: Theatrical | D5: 44929 | E5: 354949 | F5: =(E5-G5)/E5 -> 0.99838287 | G5: 574 | H5: 141863 | I5: =H5/E5 -> 0.3996715 | J5: 2270 | K5: =J5/E5 -> 0.006395285 | L5: =J5/H5 -> 0.016001353 | M5: 606 | N5: =M5/E5 -> 0.0017072875 | O5: Theatrical
A6: Friday What's On FR | B6: SCENE | C6: Theatrical | D6: 44932 | E6: 95994 | F6: =(E6-G6)/E6 -> 0.99888535 | G6: 107 | H6: 30775 | I6: =H6/E6 -> 0.32059295 | J6: 946 | K6: =J6/E6 -> 0.0098547826 | L6: =J6/H6 -> 0.030739236 | M6: 86 | N6: =M6/E6 -> 0.00089588933 | O6: Theatrical
A7: Friday What's On EN | B7: SCENE | C7: Theatrical | D7: 44932 | E7: 1750473 | F7: =(E7-G7)/E7 -> 0.99671403 | G7: 5752 | H7: 625509 | I7: =H7/E7 -> 0.35733713 | J7: 12915 | K7: =J7/E7 -> 0.0073780058 | L7: =J7/H7 -> 0.020647185 | M7: 2797 | N7: =M7/E7 -> 0.0015978538 | O7: Theatrical
A8: Friday What's On FR | B8: CONNECT | C8: Theatrical | D8: 44932 | E8: 223652 | F8: =(E8-G8)/E8 -> 0.99710711 | G8: 647 | H8: 78135 | I8: =H8/E8 -> 0.34935972 | J8: 3430 | K8: =J8/E8 -> 0.015336326 | L8: =J8/H8 -> 0.043898381 | M8: 1896 | N8: =M8/E8 -> 0.008477456 | O8: Theatrical
A9: Friday What's On EN | B9: CONNECT | C9: Theatrical | D9: 44932 | E9: 2511131 | F9: =(E9-G9)/E9 -> 0.99525075 | G9: 11926 | H9: 923449 | I9: =H9/E9 -> 0.36774226 | J9: 23859 | K9: =J9/E9 -> 0.0095012964 | L9: =J9/H9 -> 0.025836836 | M9: 11684 | N9: =M9/E9 -> 0.0046528835 | O9: Theatrical
A10: Edmonton Closure EN | B10: SCENE | C10: Theatrical | D10: 44932 | E10: 4172 | F10: =(E10-G10)/E10 -> 0.99856184 | G10: 6 | H10: 1614 | I10: =H10/E10 -> 0.38686481 | J10: 24 | K10: =J10/E10 -> 0.0057526366 | L10: =J10/H10 -> 0.014869888 | M10: 4 | N10: =M10/E10 -> 0.00095877277 | O10: Theatrical
A11: Edmonton Closure EN | B11: CONNECT | C11: Theatrical | D11: 44932 | E11: 2196 | F11: =(E11-G11)/E11 -> 0.99908925 | G11: 2 | H11: 865 | I11: =H11/E11 -> 0.393898 | J11: 15 | K11: =J11/E11 -> 0.0068306011 | L11: =J11/H11 -> 0.01734104 | M11: 4 | N11: =M11/E11 -> 0.0018214936 | O11: Theatrical
A12: Arts & Culture Newsletter FR | B12: SCENE | C12: Theatrical | D12: 44933 | E12: 1320 | F12: =(E12-G12)/E12 -> 0.99848485 | G12: 2 | H12: 655 | I12: =H12/E12 -> 0.49621212 | J12: 100 | K12: =J12/E12 -> 0.075757576 | L12: =J12/H12 -> 0.15267176 | M12: 4 | N12: =M12/E12 -> 0.003030303 | O12: Theatrical
A13: Arts & Culture Newsletter EN | B13: SCENE | C13: Theatrical | D13: 44933 | E13: 10010 | F13: =(E13-G13)/E13 -> 0.9989011 | G13: 11 | H13: 4668 | I13: =H13/E13 -> 0.46633367 | J13: 555 | K13: =J13/E13 -> 0.055444555 | L13: =J13/H13 -> 0.1188946 | M13: 7 | N13: =M13/E13 -> 0.0006993007 | O13: Theatrical
... A509: Friday What's On EN | B509: CONNECT | C509: Theatrical | D509: 45100 | E509: 2348491 | F509: =(E509-G509)/E509 -> 0.99773003 | G509: 5331 | H509: 752290 | I509: =H509/E509 -> 0.3203291 | J509: 9193 | K509: =J509/E509 -> 0.0039144285 | L509: =J509/H509 -> 0.012220022 | M509: 3179 | N509: =M509/E509 -> 0.0013536352 | O509: Theatrical
A511: All 2023 Theatrical | E511: =SUM(E2:E509) -> 265760687 | F511: =(E511-G511)/E511 -> 0.99688983 | G511: =SUM(G2:G509) -> 826560 | H511: =SUM(H2:H509) -> 96522187 | I511: =H511/E511 -> 0.36319212 | J511: =SUM(J2:J509) -> 1458556 | K511: =J511/E511 -> 0.0054882308 | L511: =J511/H511 -> 0.015111096 | M511: =SUM(M2:M509) -> 438923 | N511: =M511/E511 -> 0.0016515723
M512: =M511/J511 -> 0.30092982
A514: Campaign Monitor 2021 Industry Benchmarks (Media, Entertainment, Publishing) | I514: 0.239 | K514: 0.029 | L514: 0.124 | N514: 0.001

Sheet Store
A1: Email Name | B1: Audience | C1: Business Unit | D1: Send Date | E1: Sends | F1: Delivery Rate | G1: Overall Bounces | H1: Unique Opens | I1: Open Rate | J1: Unique Clicks | K1: CTR | L1: CTO | M1: Unsubscribes | N1: Unsubscribe Rate | O1: Reporting
A2: Movie Guide EN 24MT | B2: CONNECT | C2: Store | D2: 44932 | E2: 229503 | F2: =(E2-G2)/E2 -> 0.99866233 | G2: 307 | H2: 105460 | I2: =H2/E2 -> 0.45951469 | J2: 2616 | K2: =J2/E2 -> 0.011398544 | L2: =J2/H2 -> 0.024805614 | M2: 317 | N2: =M2/E2 -> 0.0013812456 | O2: Store
A3: Movie Guide EN | B3: CONNECT | C3: Store | D3: 44932 | E3: 327320 | F3: =(E3-G3)/E3 -> 0.9971618 | G3: 929 | H3: 123722 | I3: =H3/E3 -> 0.37798485 | J3: 3484 | K3: =J3/E3 -> 0.010644018 | L3: =J3/H3 -> 0.028159907 | M3: 473 | N3: =M3/E3 -> 0.001445069 | O3: Store
A4: Puss In Boots FR | B4: CONNECT | C4: Store | D4: 44936 | E4: 8498 | F4: =(E4-G4)/E4 -> 0.99917628 | G4: 7 | H4: 3081 | I4: =H4/E4 -> 0.3625559 | J4: 77 | K4: =J4/E4 -> 0.0090609555 | L4: =J4/H4 -> 0.024991886 | M4: 24 | N4: =M4/E4 -> 0.0028241939 | O4: Store
A5: Puss In Boots FR | B5: SCENE | C5: Store | D5: 44936 | E5: 8577 | F5: =(E5-G5)/E5 -> 0.99918386 | G5: 7 | H5: 2955 | I5: =H5/E5 -> 0.34452606 | J5: 68 | K5: =J5/E5 -> 0.00792818 | L5: =J5/H5 -> 0.023011844 | M5: 14 | N5: =M5/E5 -> 0.0016322724 | O5: Store
A6: Puss In Boots EN | B6: CONNECT | C6: Store | D6: 44936 | E6: 153349 | F6: =(E6-G6)/E6 -> 0.99861101 | G6: 213 | H6: 73892 | I6: =H6/E6 -> 0.48185511 | J6: 1128 | K6: =J6/E6 -> 0.0073557702 | L6: =J6/H6 -> 0.015265523 | M6: 359 | N6: =M6/E6 -> 0.0023410652 | O6: Store
A7: Puss In Boots EN | B7: SCENE | C7: Store | D7: 44936 | E7: 169230 | F7: =(E7-G7)/E7 -> 0.99881818 | G7: 200 | H7: 74958 | I7: =H7/E7 -> 0.44293565 | J7: 970 | K7: =J7/E7 -> 0.0057318442 | L7: =J7/H7 -> 0.01294058 | M7: 184 | N7: =M7/E7 -> 0.0010872777 | O7: Store
A8: Movie Guide EN 24MT | B8: CONNECT | C8: Store | D8: 44939 | E8: 252620 | F8: =(E8-G8)/E8 -> 0.99887974 | G8: 283 | H8: 95330 | I8: =H8/E8 -> 0.37736521 | J8: 2226 | K8: =J8/E8 -> 0.0088116539 | L8: =J8/H8 -> 0.023350467 | M8: 330 | N8: =M8/E8 -> 0.0013063099 | O8: Store
A9: Movie Guide EN | B9: CONNECT | C9: Store | D9: 44939 | E9: 334315 | F9: =(E9-G9)/E9 -> 0.99789121 | G9: 705 | H9: 101194 | I9: =H9/E9 -> 0.30269058 | J9: 2570 | K9: =J9/E9 -> 0.0076873607 | L9: =J9/H9 -> 0.025396763 | M9: 321 | N9: =M9/E9 -> 0.00096017229 | O9: Store
A10: National Popcorn Day FR | B10: SCENE | C10: Store | D10: 44944 | E10: 13312 | F10: =(E10-G10)/E10 -> 0.99939904 | G10: 8 | H10: 4857 | I10: =H10/E10 -> 0.36485877 | J10: 100 | K10: =J10/E10 -> 0.0075120192 | L10: =J10/H10 -> 0.020588841 | M10: 21 | N10: =M10/E10 -> 0.001577524 | O10: Store
A11: National Popcorn Day FR | B11: Connect | C11: Store | D11: 44944 | E11: 12562 | F11: =(E11-G11)/E11 -> 0.99872632 | G11: 16 | H11: 4407 | I11: =H11/E11 -> 0.35081993 | J11: 124 | K11: =J11/E11 -> 0.0098710396 | L11: =J11/H11 -> 0.028137055 | M11: 42 | N11: =M11/E11 -> 0.0033434167 | O11: Store
A12: National Popcorn Day EN | B12: SCENE | C12: Store | D12: 44944 | E12: 267738 | F12: =(E12-G12)/E12 -> 0.99876372 | G12: 331 | H12: 128054 | I12: =H12/E12 -> 0.47828101 | J12: 2534 | K12: =J12/E12 -> 0.0094644765 | L12: =J12/H12 -> 0.019788527 | M12: 182 | N12: =M12/E12 -> 0.00067976903 | O12: Store
A13: National Popcorn Day EN | B13: Connect | C13: Store | D13: 44944 | E13: 216958 | F13: =(E13-G13)/E13 -> 0.99808258 | G13: 416 | H13: 109518 | I13: =H13/E13 -> 0.50478895 | J13: 2556 | K13: =J13/E13 -> 0.011781082 | L13: =J13/H13 -> 0.023338629 | M13: 504 | N13: =M13/E13 -> 0.0023230303 | O13: Store
... A115: Movie Guide FR | B115: CONNECT | C115: Store | D115: 45101 | E115: 14954 | F115: =(E115-G115)/E115 -> 0.99819446 | G115: 27 | H115: 4698 | I115: =H115/E115 -> 0.31416343 | J115: 191 | K115: =J115/E115 -> 0.012772502 | L115: =J115/H115 -> 0.040655598 | M115: 16 | N115: =M115/E115 -> 0.0010699478 | O115: Store
A117: All 2023 Store | E117: =SUM(E2:E115) -> 33780908 | F117: =(E117-G117)/E117 -> 0.99648011 | G117: =SUM(G2:G115) -> 118905 | H117: =SUM(H2:H115) -> 14555673 | I117: =H117/E117 -> 0.4308846 | J117: =SUM(J2:J115) -> 239749 | K117: =J117/E117 -> 0.0070971745 | L117: =J117/H117 -> 0.016471172 | M117: =SUM(M2:M115) -> 46124 | N117: =M117/E117 -> 0.0013653866
M118: =M117/J117 -> 0.19238454
A120: Campaign Monitor 2021 Industry Benchmarks (Media, Entertainment, Publishing) | I120: 0.239 | K120: 0.029 | L120: 0.124 | N120: 0.001

Sheet Scene+ Offer Only
A1: Email Name | B1: Audience | C1: Business Unit | D1: Send Date | E1: Sends | F1: Delivery Rate | G1: Overall Bounces | H1: Unique Opens | I1: Open Rate | J1: Unique Clicks | K1: CTR | L1: CTO | M1: Unsubscribes | N1: Unsubscribe Rate | O1: Reporting
A2: Scene Redemption Offer FR | B2: SCENE | C2: Scene+ Offer Only | D2: 44945 | E2: 58305 | F2: =(E2-G2)/E2 -> 0.99938256 | G2: 36 | H2: 20830 | I2: =H2/E2 -> 0.35725924 | J2: 405 | K2: =J2/E2 -> 0.006946231 | L2: =J2/H2 -> 0.019443111 | M2: 23 | N2: =M2/E2 -> 0.00039447732 | O2: Scene+ Offer Only
A3: Scene Redemption Offer EN | B3: SCENE | C3: Scene+ Offer Only | D3: 44945 | E3: 1048165 | F3: =(E3-G3)/E3 -> 0.99827985 | G3: 1803 | H3: 420124 | I3: =H3/E3 -> 0.40081857 | J3: 5939 | K3: =J3/E3 -> 0.0056660926 | L3: =J3/H3 -> 0.014136303 | M3: 513 | N3: =M3/E3 -> 0.00048942676 | O3: Scene+ Offer Only
A4: 1M Points Contest FR | B4: SCENE | C4: Scene+ Offer Only | D4: 44958 | E4: 118612 | F4: =(E4-G4)/E4 -> 0.9992075 | G4: 94 | H4: 41444 | I4: =H4/E4 -> 0.34940815 | J4: 3187 | K4: =J4/E4 -> 0.026869119 | L4: =J4/H4 -> 0.076898948 | M4: 67 | N4: =M4/E4 -> 0.00056486696 | O4: Scene+ Offer Only
A5: 1M Points Contest FR | B5: CONNECT | C5: Scene+ Offer Only | D5: 44958 | E5: 225370 | F5: =(E5-G5)/E5 -> 0.99866442 | G5: 301 | H5: 78840 | I5: =H5/E5 -> 0.34982473 | J5: 2842 | K5: =J5/E5 -> 0.012610374 | L5: =J5/H5 -> 0.036047692 | M5: 1119 | N5: =M5/E5 -> 0.0049651684 | O5: Scene+ Offer Only
A6: 1M Points Contest EN | B6: SCENE | C6: Scene+ Offer Only | D6: 44958 | E6: 2084287 | F6: =(E6-G6)/E6 -> 0.99772824 | G6: 4735 | H6: 801636 | I6: =H6/E6 -> 0.38460922 | J6: 47678 | K6: =J6/E6 -> 0.022874969 | L6: =J6/H6 -> 0.059475872 | M6: 1805 | N6: =M6/E6 -> 0.00086600358 | O6: Scene+ Offer Only
A7: 1M Points Contest EN | B7: CONNECT | C7: Scene+ Offer Only | D7: 44958 | E7: 2403003 | F7: =(E7-G7)/E7 -> 0.99798627 | G7: 4839 | H7: 889875 | I7: =H7/E7 -> 0.37031789 | J7: 21323 | K7: =J7/E7 -> 0.0088734804 | L7: =J7/H7 -> 0.023961792 | M7: 8219 | N7: =M7/E7 -> 0.0034203037 | O7: Scene+ Offer Only
A8: Scene Acquisition Offer FR | B8: CONNECT | C8: Scene+ Offer Only | D8: 44959 | E8: 5558 | F8: =(E8-G8)/E8 -> 0.99928032 | G8: 4 | H8: 1870 | I8: =H8/E8 -> 0.33645196 | J8: 48 | K8: =J8/E8 -> 0.0086362001 | L8: =J8/H8 -> 0.025668449 | M8: 47 | N8: =M8/E8 -> 0.0084562792 | O8: Scene+ Offer Only
A9: Scene Acquisition Offer EN | B9: CONNECT | C9: Scene+ Offer Only | D9: 44959 | E9: 49754 | F9: =(E9-G9)/E9 -> 0.99784942 | G9: 107 | H9: 17854 | I9: =H9/E9 -> 0.35884552 | J9: 414 | K9: =J9/E9 -> 0.008320939 | L9: =J9/H9 -> 0.023188081 | M9: 258 | N9: =M9/E9 -> 0.0051855127 | O9: Scene+ Offer Only
A10: Scene Acquisition No Offer FR | B10: CONNECT | C10: Scene+ Offer Only | D10: 44959 | E10: 5547 | F10: =(E10-G10)/E10 -> 0.99801695 | G10: 11 | H10: 1904 | I10: =H10/E10 -> 0.3432486 | J10: 45 | K10: =J10/E10 -> 0.0081124932 | L10: =J10/H10 -> 0.023634454 | M10: 43 | N10: =M10/E10 -> 0.007751938 | O10: Scene+ Offer Only
A11: Scene Acquisition No Offer EN | B11: CONNECT | C11: Scene+ Offer Only | D11: 44959 | E11: 49774 | F11: =(E11-G11)/E11 -> 0.99762928 | G11: 118 | H11: 17936 | I11: =H11/E11 -> 0.36034878 | J11: 350 | K11: =J11/E11 -> 0.0070317837 | L11: =J11/H11 -> 0.019513827 | M11: 261 | N11: =M11/E11 -> 0.0052437015 | O11: Scene+ Offer Only
